<?xml version="1.0"?>
<sdf version='1.7'>
  <world name='default'>
    <light name='sun' type='directional'>
      <cast_shadows>1</cast_shadows>
      <pose>0 0 10 0 -0 0</pose>
      <diffuse>0.8 0.8 0.8 1</diffuse>
      <specular>0.2 0.2 0.2 1</specular>
      <attenuation>
        <range>1000</range>
        <constant>0.9</constant>
        <linear>0.01</linear>
        <quadratic>0.001</quadratic>
      </attenuation>
      <direction>-0.5 0.1 -0.9</direction>
      <spot>
        <inner_angle>0</inner_angle>
        <outer_angle>0</outer_angle>
        <falloff>0</falloff>
      </spot>
    </light>
    <model name='ground_plane'>
      <static>1</static>
      <link name='link'>
        <collision name='collision'>
          <geometry>
            <plane>
              <normal>0 0 1</normal>
              <size>100 100</size>
            </plane>
          </geometry>
          <surface>
            <friction>
              <ode>
                <mu>100</mu>
                <mu2>50</mu2>
              </ode>
              <torsional>
                <ode/>
              </torsional>
            </friction>
            <contact>
              <ode/>
            </contact>
            <bounce/>
          </surface>
          <max_contacts>10</max_contacts>
        </collision>
        <visual name='visual'>
          <cast_shadows>0</cast_shadows>
          <geometry>
            <plane>
              <normal>0 0 1</normal>
              <size>100 100</size>
            </plane>
          </geometry>
          <material>
            <script>
              <uri>file://media/materials/scripts/gazebo.material</uri>
              <name>Gazebo/Grey</name>
            </script>
          </material>
        </visual>
        <self_collide>0</self_collide>
        <enable_wind>0</enable_wind>
        <kinematic>0</kinematic>
      </link>
    </model>
    <gravity>0 0 -9.8</gravity>
    <magnetic_field>6e-06 2.3e-05 -4.2e-05</magnetic_field>
    <atmosphere type='adiabatic'/>
    <physics type='ode'>
      <max_step_size>0.001</max_step_size>
      <real_time_factor>1</real_time_factor>
      <real_time_update_rate>1000</real_time_update_rate>
    </physics>
    <scene>
      <ambient>0.4 0.4 0.4 1</ambient>
      <background>0.7 0.7 0.7 1</background>
      <shadows>1</shadows>
    </scene>
    <audio>
      <device>default</device>
    </audio>
    <wind/>
    <spherical_coordinates>
      <surface_model>EARTH_WGS84</surface_model>
      <latitude_deg>0</latitude_deg>
      <longitude_deg>0</longitude_deg>
      <elevation>0</elevation>
      <heading_deg>0</heading_deg>
    </spherical_coordinates>
    <model name='walls'>
      <pose>2.77787 1.7398 0 0 -0 0</pose>
      <link name='Wall_13'>
        <collision name='Wall_13_Collision'>
          <geometry>
            <box>
              <size>15 0.15 2.5</size>
            </box>
          </geometry>
          <pose>0 0 1.25 0 -0 0</pose>
          <max_contacts>10</max_contacts>
          <surface>
            <contact>
              <ode/>
            </contact>
            <bounce/>
            <friction>
              <torsional>
                <ode/>
              </torsional>
              <ode/>
            </friction>
          </surface>
        </collision>
        <visual name='Wall_13_Visual'>
          <pose>0 0 1.25 0 -0 0</pose>
          <geometry>
            <box>
              <size>15 0.15 2.5</size>
            </box>
          </geometry>
          <material>
            <script>
              <uri>file://media/materials/scripts/gazebo.material</uri>
              <name>Gazebo/Grey</name>
            </script>
            <ambient>1 1 1 1</ambient>
          </material>
          <meta>
            <layer>0</layer>
          </meta>
        </visual>
        <pose>-0 -7.425 0 0 -0 0</pose>
        <self_collide>0</self_collide>
        <enable_wind>0</enable_wind>
        <kinematic>0</kinematic>
      </link>
      <link name='Wall_14'>
        <collision name='Wall_14_Collision'>
          <geometry>
            <box>
              <size>0.15 0.15 2.5</size>
            </box>
          </geometry>
          <pose>0 0 1.25 0 -0 0</pose>
          <max_contacts>10</max_contacts>
          <surface>
            <contact>
              <ode/>
            </contact>
            <bounce/>
            <friction>
              <torsional>
                <ode/>
              </torsional>
              <ode/>
            </friction>
          </surface>
        </collision>
        <visual name='Wall_14_Visual'>
          <pose>0 0 1.25 0 -0 0</pose>
          <geometry>
            <box>
              <size>0.15 0.15 2.5</size>
            </box>
          </geometry>
          <material>
            <script>
              <uri>file://media/materials/scripts/gazebo.material</uri>
              <name>Gazebo/Grey</name>
            </script>
            <ambient>1 1 1 1</ambient>
          </material>
          <meta>
            <layer>0</layer>
          </meta>
        </visual>
        <pose>7.425 -7.425 0 0 -0 0</pose>
        <self_collide>0</self_collide>
        <enable_wind>0</enable_wind>
        <kinematic>0</kinematic>
      </link>
      <link name='Wall_17'>
        <collision name='Wall_17_Collision'>
          <geometry>
            <box>
              <size>15 0.15 2.5</size>
            </box>
          </geometry>
          <pose>0 0 1.25 0 -0 0</pose>
          <max_contacts>10</max_contacts>
          <surface>
            <contact>
              <ode/>
            </contact>
            <bounce/>
            <friction>
              <torsional>
                <ode/>
              </torsional>
              <ode/>
            </friction>
          </surface>
        </collision>
        <visual name='Wall_17_Visual'>
          <pose>0 0 1.25 0 -0 0</pose>
          <geometry>
            <box>
              <size>15 0.15 2.5</size>
            </box>
          </geometry>
          <material>
            <script>
              <uri>file://media/materials/scripts/gazebo.material</uri>
              <name>Gazebo/Grey</name>
            </script>
            <ambient>1 1 1 1</ambient>
          </material>
          <meta>
            <layer>0</layer>
          </meta>
        </visual>
        <pose>7.425 0 0 0 -0 1.5708</pose>
        <self_collide>0</self_collide>
        <enable_wind>0</enable_wind>
        <kinematic>0</kinematic>
      </link>
      <link name='Wall_19'>
        <collision name='Wall_19_Collision'>
          <geometry>
            <box>
              <size>15 0.15 2.5</size>
            </box>
          </geometry>
          <pose>0 0 1.25 0 -0 0</pose>
          <max_contacts>10</max_contacts>
          <surface>
            <contact>
              <ode/>
            </contact>
            <bounce/>
            <friction>
              <torsional>
                <ode/>
              </torsional>
              <ode/>
            </friction>
          </surface>
        </collision>
        <visual name='Wall_19_Visual'>
          <pose>0 0 1.25 0 -0 0</pose>
          <geometry>
            <box>
              <size>15 0.15 2.5</size>
            </box>
          </geometry>
          <material>
            <script>
              <uri>file://media/materials/scripts/gazebo.material</uri>
              <name>Gazebo/Grey</name>
            </script>
            <ambient>1 1 1 1</ambient>
          </material>
          <meta>
            <layer>0</layer>
          </meta>
        </visual>
        <pose>-0 7.425 0 0 -0 3.14159</pose>
        <self_collide>0</self_collide>
        <enable_wind>0</enable_wind>
        <kinematic>0</kinematic>
      </link>
      <link name='Wall_20'>
        <collision name='Wall_20_Collision'>
          <geometry>
            <box>
              <size>0.15 0.15 2.5</size>
            </box>
          </geometry>
          <pose>0 0 1.25 0 -0 0</pose>
          <max_contacts>10</max_contacts>
          <surface>
            <contact>
              <ode/>
            </contact>
            <bounce/>
            <friction>
              <torsional>
                <ode/>
              </torsional>
              <ode/>
            </friction>
          </surface>
        </collision>
        <visual name='Wall_20_Visual'>
          <pose>0 0 1.25 0 -0 0</pose>
          <geometry>
            <box>
              <size>0.15 0.15 2.5</size>
            </box>
          </geometry>
          <material>
            <script>
              <uri>file://media/materials/scripts/gazebo.material</uri>
              <name>Gazebo/Grey</name>
            </script>
            <ambient>1 1 1 1</ambient>
          </material>
          <meta>
            <layer>0</layer>
          </meta>
        </visual>
        <pose>-7.425 7.425 0 0 -0 0</pose>
        <self_collide>0</self_collide>
        <enable_wind>0</enable_wind>
        <kinematic>0</kinematic>
      </link>
      <link name='Wall_21'>
        <collision name='Wall_21_Collision'>
          <geometry>
            <box>
              <size>15 0.15 2.5</size>
            </box>
          </geometry>
          <pose>0 0 1.25 0 -0 0</pose>
          <max_contacts>10</max_contacts>
          <surface>
            <contact>
              <ode/>
            </contact>
            <bounce/>
            <friction>
              <torsional>
                <ode/>
              </torsional>
              <ode/>
            </friction>
          </surface>
        </collision>
        <visual name='Wall_21_Visual'>
          <pose>0 0 1.25 0 -0 0</pose>
          <geometry>
            <box>
              <size>15 0.15 2.5</size>
            </box>
          </geometry>
          <material>
            <script>
              <uri>file://media/materials/scripts/gazebo.material</uri>
              <name>Gazebo/Grey</name>
            </script>
            <ambient>1 1 1 1</ambient>
          </material>
          <meta>
            <layer>0</layer>
          </meta>
        </visual>
        <pose>-7.425 0 0 0 -0 -1.5708</pose>
        <self_collide>0</self_collide>
        <enable_wind>0</enable_wind>
        <kinematic>0</kinematic>
      </link>
      <static>1</static>
    </model>
    <model name='fire_hydrant'>
      <static>1</static>
      <link name='link'>
        <collision name='collision'>
          <geometry>
            <mesh>
              <uri>model://fire_hydrant/meshes/fire_hydrant.dae</uri>
            </mesh>
          </geometry>
          <max_contacts>10</max_contacts>
          <surface>
            <contact>
              <ode/>
            </contact>
            <bounce/>
            <friction>
              <torsional>
                <ode/>
              </torsional>
              <ode/>
            </friction>
          </surface>
        </collision>
        <visual name='visual'>
          <geometry>
            <mesh>
              <uri>model://fire_hydrant/meshes/fire_hydrant.dae</uri>
            </mesh>
          </geometry>
        </visual>
        <self_collide>0</self_collide>
        <enable_wind>0</enable_wind>
        <kinematic>0</kinematic>
      </link>
      <pose>-4.35255 8.86049 0 0 -0 0</pose>
    </model>
    <model name='VendingMachine'>
      <link name='body'>
        <pose>0 0 0 0 -0 0</pose>
        <visual name='visual'>
          <geometry>
            <mesh>
              <uri>model://VendingMachine/meshes/VendingMachine.obj</uri>
            </mesh>
          </geometry>
        </visual>
        <collision name='collision'>
          <geometry>
            <mesh>
              <uri>model://VendingMachine/meshes/VendingMachine.obj</uri>
            </mesh>
          </geometry>
          <max_contacts>10</max_contacts>
          <surface>
            <contact>
              <ode/>
            </contact>
            <bounce/>
            <friction>
              <torsional>
                <ode/>
              </torsional>
              <ode/>
            </friction>
          </surface>
        </collision>
        <self_collide>0</self_collide>
        <inertial>
          <pose>0 0 0 0 -0 0</pose>
          <inertia>
            <ixx>1</ixx>
            <ixy>0</ixy>
            <ixz>0</ixz>
            <iyy>1</iyy>
            <iyz>0</iyz>
            <izz>1</izz>
          </inertia>
          <mass>1</mass>
        </inertial>
        <enable_wind>0</enable_wind>
        <kinematic>0</kinematic>
      </link>
      <pose>-4.2473 -4.8209 0 0 -0 0</pose>
    </model>
    <model name='fire_hose_long_curled'>
      <pose>-4.24037 7.80537 0.055 0 -0 0</pose>
      <link name='coupling'>
        <inertial>
          <pose>-0.07 0 0 0 -0 0</pose>
          <mass>0.1</mass>
          <inertia>
            <ixx>0.01</ixx>
            <ixy>0</ixy>
            <ixz>0</ixz>
            <iyy>0.01</iyy>
            <iyz>0</iyz>
            <izz>0.01</izz>
          </inertia>
        </inertial>
        <collision name='coupling_collision'>
          <pose>-0.01 0 0 0 -1.57079 0</pose>
          <geometry>
            <mesh>
              <scale>0.4 0.4 0.8</scale>
              <uri>model://fire_hose_long_curled/meshes/coupling_hexagon.dae</uri>
            </mesh>
          </geometry>
          <surface>
            <friction>
              <ode>
                <mu>1</mu>
                <mu2>1</mu2>
              </ode>
              <torsional>
                <ode/>
              </torsional>
            </friction>
            <contact>
              <ode/>
            </contact>
            <bounce/>
          </surface>
          <max_contacts>10</max_contacts>
        </collision>
        <visual name='coupling_vis'>
          <pose>-0.01 0 0 0 -1.57079 0</pose>
          <geometry>
            <mesh>
              <scale>0.4 0.4 0.8</scale>
              <uri>model://fire_hose_long_curled/meshes/coupling_hexagon.dae</uri>
            </mesh>
          </geometry>
          <material>
            <script>
              <uri>model://fire_hose_long_curled/materials/scripts</uri>
              <uri>model://fire_hose_long_curled/materials/textures</uri>
              <name>fire_hose_long_curled/fire_hose_coupling</name>
            </script>
          </material>
        </visual>
        <visual name='attachment_vis'>
          <pose>-0.1225 0 0 0 -1.57079 0</pose>
          <geometry>
            <mesh>
              <uri>model://fire_hose_long_curled/meshes/connector.dae</uri>
            </mesh>
          </geometry>
          <material>
            <script>
              <uri>model://fire_hose_long_curled/materials/scripts</uri>
              <uri>model://fire_hose_long_curled/materials/textures</uri>
              <name>fire_hose_long_curled/fire_hose_red_coupling</name>
            </script>
          </material>
        </visual>
        <collision name='attachment_col'>
          <pose>-0.1225 0 0 0 -1.57079 0</pose>
          <geometry>
            <cylinder>
              <length>0.025</length>
              <radius>0.055</radius>
            </cylinder>
          </geometry>
          <surface>
            <contact>
              <ode>
                <min_depth>0.005</min_depth>
              </ode>
            </contact>
            <friction>
              <ode>
                <mu>1</mu>
                <mu2>1</mu2>
              </ode>
              <torsional>
                <ode/>
              </torsional>
            </friction>
            <bounce/>
          </surface>
          <max_contacts>10</max_contacts>
        </collision>
        <self_collide>0</self_collide>
        <enable_wind>0</enable_wind>
        <kinematic>0</kinematic>
      </link>
      <link name='link_00'>
        <gravity>1</gravity>
        <pose>0.1 0 0 0 -0 0</pose>
        <inertial>
          <mass>0.1</mass>
          <pose>0.1 0 0 0 -0 0</pose>
          <inertia>
            <ixx>0.01</ixx>
            <ixy>0</ixy>
            <ixz>0</ixz>
            <iyy>0.01</iyy>
            <iyz>0</iyz>
            <izz>0.01</izz>
          </inertia>
        </inertial>
        <visual name='sphere'>
          <geometry>
            <sphere>
              <radius>0.025</radius>
            </sphere>
          </geometry>
          <material>
            <script>
              <uri>model://fire_hose_long_curled/materials/scripts</uri>
              <uri>model://fire_hose_long_curled/materials/textures</uri>
              <name>fire_hose_long_curled/fire_hose_canvas</name>
            </script>
          </material>
        </visual>
        <self_collide>0</self_collide>
        <enable_wind>0</enable_wind>
        <kinematic>0</kinematic>
      </link>
      <link name='link_01'>
        <gravity>1</gravity>
        <pose>0.1 0 0 0 -0 0</pose>
        <inertial>
          <mass>0.1</mass>
          <pose>0.1 0 0 0 -0 0</pose>
          <inertia>
            <ixx>0.01</ixx>
            <ixy>0</ixy>
            <ixz>0</ixz>
            <iyy>0.01</iyy>
            <iyz>0</iyz>
            <izz>0.01</izz>
          </inertia>
        </inertial>
        <collision name='collision'>
          <pose>0.1 0 0 0 1.57079 0</pose>
          <geometry>
            <cylinder>
              <length>0.2</length>
              <radius>0.025</radius>
            </cylinder>
          </geometry>
          <surface>
            <contact>
              <ode>
                <min_depth>0.005</min_depth>
              </ode>
            </contact>
            <friction>
              <ode>
                <mu>1</mu>
                <mu2>1</mu2>
              </ode>
              <torsional>
                <ode/>
              </torsional>
            </friction>
            <bounce/>
          </surface>
          <max_contacts>10</max_contacts>
        </collision>
        <visual name='visual'>
          <pose>0.1 0 0 0 1.57079 0</pose>
          <geometry>
            <cylinder>
              <length>0.2</length>
              <radius>0.025</radius>
            </cylinder>
          </geometry>
          <material>
            <script>
              <uri>model://fire_hose_long_curled/materials/scripts</uri>
              <uri>model://fire_hose_long_curled/materials/textures</uri>
              <name>fire_hose_long_curled/fire_hose_canvas</name>
            </script>
          </material>
        </visual>
        <self_collide>0</self_collide>
        <enable_wind>0</enable_wind>
        <kinematic>0</kinematic>
      </link>
      <link name='link_02'>
        <gravity>1</gravity>
        <pose>0.3 0 0 0 -0 0</pose>
        <inertial>
          <mass>0.1</mass>
          <pose>0.1 0 0 0 -0 0</pose>
          <inertia>
            <ixx>0.01</ixx>
            <ixy>0</ixy>
            <ixz>0</ixz>
            <iyy>0.01</iyy>
            <iyz>0</iyz>
            <izz>0.01</izz>
          </inertia>
        </inertial>
        <collision name='collision'>
          <pose>0.1 0 0 0 1.57079 0</pose>
          <geometry>
            <cylinder>
              <length>0.2</length>
              <radius>0.025</radius>
            </cylinder>
          </geometry>
          <surface>
            <contact>
              <ode>
                <min_depth>0.005</min_depth>
              </ode>
            </contact>
            <friction>
              <ode>
                <mu>1</mu>
                <mu2>1</mu2>
              </ode>
              <torsional>
                <ode/>
              </torsional>
            </friction>
            <bounce/>
          </surface>
          <max_contacts>10</max_contacts>
        </collision>
        <visual name='visual'>
          <pose>0.1 0 0 0 1.57079 0</pose>
          <geometry>
            <cylinder>
              <length>0.2</length>
              <radius>0.025</radius>
            </cylinder>
          </geometry>
          <material>
            <script>
              <uri>model://fire_hose_long_curled/materials/scripts</uri>
              <uri>model://fire_hose_long_curled/materials/textures</uri>
              <name>fire_hose_long_curled/fire_hose_canvas</name>
            </script>
          </material>
        </visual>
        <visual name='sphere'>
          <geometry>
            <sphere>
              <radius>0.025</radius>
            </sphere>
          </geometry>
          <material>
            <script>
              <uri>model://fire_hose_long_curled/materials/scripts</uri>
              <uri>model://fire_hose_long_curled/materials/textures</uri>
              <name>fire_hose_long_curled/fire_hose_canvas</name>
            </script>
          </material>
        </visual>
        <self_collide>0</self_collide>
        <enable_wind>0</enable_wind>
        <kinematic>0</kinematic>
      </link>
      <link name='link_03'>
        <gravity>1</gravity>
        <pose>0.5 0 0 0 -0 0</pose>
        <inertial>
          <mass>0.1</mass>
          <pose>0.1 0 0 0 -0 0</pose>
          <inertia>
            <ixx>0.01</ixx>
            <ixy>0</ixy>
            <ixz>0</ixz>
            <iyy>0.01</iyy>
            <iyz>0</iyz>
            <izz>0.01</izz>
          </inertia>
        </inertial>
        <collision name='collision'>
          <pose>0.1 0 0 0 1.57079 0</pose>
          <geometry>
            <cylinder>
              <length>0.2</length>
              <radius>0.025</radius>
            </cylinder>
          </geometry>
          <surface>
            <contact>
              <ode>
                <min_depth>0.005</min_depth>
              </ode>
            </contact>
            <friction>
              <ode>
                <mu>1</mu>
                <mu2>1</mu2>
              </ode>
              <torsional>
                <ode/>
              </torsional>
            </friction>
            <bounce/>
          </surface>
          <max_contacts>10</max_contacts>
        </collision>
        <visual name='visual'>
          <pose>0.1 0 0 0 1.57079 0</pose>
          <geometry>
            <cylinder>
              <length>0.2</length>
              <radius>0.025</radius>
            </cylinder>
          </geometry>
          <material>
            <script>
              <uri>model://fire_hose_long_curled/materials/scripts</uri>
              <uri>model://fire_hose_long_curled/materials/textures</uri>
              <name>fire_hose_long_curled/fire_hose_canvas</name>
            </script>
          </material>
        </visual>
        <visual name='sphere'>
          <geometry>
            <sphere>
              <radius>0.025</radius>
            </sphere>
          </geometry>
          <material>
            <script>
              <uri>model://fire_hose_long_curled/materials/scripts</uri>
              <uri>model://fire_hose_long_curled/materials/textures</uri>
              <name>fire_hose_long_curled/fire_hose_canvas</name>
            </script>
          </material>
        </visual>
        <self_collide>0</self_collide>
        <enable_wind>0</enable_wind>
        <kinematic>0</kinematic>
      </link>
      <link name='link_04'>
        <gravity>1</gravity>
        <pose>0.7 0 0 0 -0 0</pose>
        <inertial>
          <mass>0.1</mass>
          <pose>0.1 0 0 0 -0 0</pose>
          <inertia>
            <ixx>0.01</ixx>
            <ixy>0</ixy>
            <ixz>0</ixz>
            <iyy>0.01</iyy>
            <iyz>0</iyz>
            <izz>0.01</izz>
          </inertia>
        </inertial>
        <collision name='collision'>
          <pose>0.1 0 0 0 1.57079 0</pose>
          <geometry>
            <cylinder>
              <length>0.2</length>
              <radius>0.025</radius>
            </cylinder>
          </geometry>
          <surface>
            <contact>
              <ode>
                <min_depth>0.005</min_depth>
              </ode>
            </contact>
            <friction>
              <ode>
                <mu>1</mu>
                <mu2>1</mu2>
              </ode>
              <torsional>
                <ode/>
              </torsional>
            </friction>
            <bounce/>
          </surface>
          <max_contacts>10</max_contacts>
        </collision>
        <visual name='visual'>
          <pose>0.1 0 0 0 1.57079 0</pose>
          <geometry>
            <cylinder>
              <length>0.2</length>
              <radius>0.025</radius>
            </cylinder>
          </geometry>
          <material>
            <script>
              <uri>model://fire_hose_long_curled/materials/scripts</uri>
              <uri>model://fire_hose_long_curled/materials/textures</uri>
              <name>fire_hose_long_curled/fire_hose_canvas</name>
            </script>
          </material>
        </visual>
        <visual name='sphere'>
          <geometry>
            <sphere>
              <radius>0.025</radius>
            </sphere>
          </geometry>
          <material>
            <script>
              <uri>model://fire_hose_long_curled/materials/scripts</uri>
              <uri>model://fire_hose_long_curled/materials/textures</uri>
              <name>fire_hose_long_curled/fire_hose_canvas</name>
            </script>
          </material>
        </visual>
        <self_collide>0</self_collide>
        <enable_wind>0</enable_wind>
        <kinematic>0</kinematic>
      </link>
      <link name='link_05'>
        <gravity>1</gravity>
        <pose>0.9 0 0 0 -0 0</pose>
        <inertial>
          <mass>0.1</mass>
          <pose>0.1 0 0 0 -0 0</pose>
          <inertia>
            <ixx>0.01</ixx>
            <ixy>0</ixy>
            <ixz>0</ixz>
            <iyy>0.01</iyy>
            <iyz>0</iyz>
            <izz>0.01</izz>
          </inertia>
        </inertial>
        <collision name='collision'>
          <pose>0.1 0 0 0 1.57079 0</pose>
          <geometry>
            <cylinder>
              <length>0.2</length>
              <radius>0.025</radius>
            </cylinder>
          </geometry>
          <surface>
            <contact>
              <ode>
                <min_depth>0.005</min_depth>
              </ode>
            </contact>
            <friction>
              <ode>
                <mu>1</mu>
                <mu2>1</mu2>
              </ode>
              <torsional>
                <ode/>
              </torsional>
            </friction>
            <bounce/>
          </surface>
          <max_contacts>10</max_contacts>
        </collision>
        <visual name='visual'>
          <pose>0.1 0 0 0 1.57079 0</pose>
          <geometry>
            <cylinder>
              <length>0.2</length>
              <radius>0.025</radius>
            </cylinder>
          </geometry>
          <material>
            <script>
              <uri>model://fire_hose_long_curled/materials/scripts</uri>
              <uri>model://fire_hose_long_curled/materials/textures</uri>
              <name>fire_hose_long_curled/fire_hose_canvas</name>
            </script>
          </material>
        </visual>
        <visual name='sphere'>
          <geometry>
            <sphere>
              <radius>0.025</radius>
            </sphere>
          </geometry>
          <material>
            <script>
              <uri>model://fire_hose_long_curled/materials/scripts</uri>
              <uri>model://fire_hose_long_curled/materials/textures</uri>
              <name>fire_hose_long_curled/fire_hose_canvas</name>
            </script>
          </material>
        </visual>
        <self_collide>0</self_collide>
        <enable_wind>0</enable_wind>
        <kinematic>0</kinematic>
      </link>
      <link name='link_06'>
        <gravity>1</gravity>
        <pose>1.1 0 0 0 0 -0.785</pose>
        <inertial>
          <mass>0.1</mass>
          <pose>0.0875 0 0 0 -0 0</pose>
          <inertia>
            <ixx>0.01</ixx>
            <ixy>0</ixy>
            <ixz>0</ixz>
            <iyy>0.01</iyy>
            <iyz>0</iyz>
            <izz>0.01</izz>
          </inertia>
        </inertial>
        <collision name='collision'>
          <pose>0.0875 0 0 0 1.57079 0</pose>
          <geometry>
            <cylinder>
              <length>0.175</length>
              <radius>0.025</radius>
            </cylinder>
          </geometry>
          <surface>
            <contact>
              <ode>
                <min_depth>0.005</min_depth>
              </ode>
            </contact>
            <friction>
              <ode>
                <mu>1</mu>
                <mu2>1</mu2>
              </ode>
              <torsional>
                <ode/>
              </torsional>
            </friction>
            <bounce/>
          </surface>
          <max_contacts>10</max_contacts>
        </collision>
        <visual name='visual'>
          <pose>0.0875 0 0 0 1.57079 0</pose>
          <geometry>
            <cylinder>
              <length>0.175</length>
              <radius>0.025</radius>
            </cylinder>
          </geometry>
          <material>
            <script>
              <uri>model://fire_hose_long_curled/materials/scripts</uri>
              <uri>model://fire_hose_long_curled/materials/textures</uri>
              <name>fire_hose_long_curled/fire_hose_canvas</name>
            </script>
          </material>
        </visual>
        <visual name='sphere'>
          <geometry>
            <sphere>
              <radius>0.025</radius>
            </sphere>
          </geometry>
          <material>
            <script>
              <uri>model://fire_hose_long_curled/materials/scripts</uri>
              <uri>model://fire_hose_long_curled/materials/textures</uri>
              <name>fire_hose_long_curled/fire_hose_canvas</name>
            </script>
          </material>
        </visual>
        <self_collide>0</self_collide>
        <enable_wind>0</enable_wind>
        <kinematic>0</kinematic>
      </link>
      <link name='link_07'>
        <gravity>1</gravity>
        <pose>1.227 -0.127 0 0 0 -2.3415</pose>
        <inertial>
          <mass>0.1</mass>
          <pose>0.0875 0 0 0 -0 0</pose>
          <inertia>
            <ixx>0.01</ixx>
            <ixy>0</ixy>
            <ixz>0</ixz>
            <iyy>0.01</iyy>
            <iyz>0</iyz>
            <izz>0.01</izz>
          </inertia>
        </inertial>
        <collision name='collision'>
          <pose>0.0875 0 0 0 1.57079 0</pose>
          <geometry>
            <cylinder>
              <length>0.175</length>
              <radius>0.025</radius>
            </cylinder>
          </geometry>
          <surface>
            <contact>
              <ode>
                <min_depth>0.005</min_depth>
              </ode>
            </contact>
            <friction>
              <ode>
                <mu>1</mu>
                <mu2>1</mu2>
              </ode>
              <torsional>
                <ode/>
              </torsional>
            </friction>
            <bounce/>
          </surface>
          <max_contacts>10</max_contacts>
        </collision>
        <visual name='visual'>
          <pose>0.0875 0 0 0 1.57079 0</pose>
          <geometry>
            <cylinder>
              <length>0.175</length>
              <radius>0.025</radius>
            </cylinder>
          </geometry>
          <material>
            <script>
              <uri>model://fire_hose_long_curled/materials/scripts</uri>
              <uri>model://fire_hose_long_curled/materials/textures</uri>
              <name>fire_hose_long_curled/fire_hose_canvas</name>
            </script>
          </material>
        </visual>
        <visual name='sphere'>
          <geometry>
            <sphere>
              <radius>0.025</radius>
            </sphere>
          </geometry>
          <material>
            <script>
              <uri>model://fire_hose_long_curled/materials/scripts</uri>
              <uri>model://fire_hose_long_curled/materials/textures</uri>
              <name>fire_hose_long_curled/fire_hose_canvas</name>
            </script>
          </material>
        </visual>
        <self_collide>0</self_collide>
        <enable_wind>0</enable_wind>
        <kinematic>0</kinematic>
      </link>
      <link name='link_08'>
        <gravity>1</gravity>
        <pose>1.1 -0.254 0 0 0 -3.1415</pose>
        <inertial>
          <mass>0.1</mass>
          <pose>0.1 0 0 0 -0 0</pose>
          <inertia>
            <ixx>0.01</ixx>
            <ixy>0</ixy>
            <ixz>0</ixz>
            <iyy>0.01</iyy>
            <iyz>0</iyz>
            <izz>0.01</izz>
          </inertia>
        </inertial>
        <collision name='collision'>
          <pose>0.1 0 0 0 1.57079 0</pose>
          <geometry>
            <cylinder>
              <length>0.2</length>
              <radius>0.025</radius>
            </cylinder>
          </geometry>
          <surface>
            <contact>
              <ode>
                <min_depth>0.005</min_depth>
              </ode>
            </contact>
            <friction>
              <ode>
                <mu>1</mu>
                <mu2>1</mu2>
              </ode>
              <torsional>
                <ode/>
              </torsional>
            </friction>
            <bounce/>
          </surface>
          <max_contacts>10</max_contacts>
        </collision>
        <visual name='visual'>
          <pose>0.1 0 0 0 1.57079 0</pose>
          <geometry>
            <cylinder>
              <length>0.2</length>
              <radius>0.025</radius>
            </cylinder>
          </geometry>
          <material>
            <script>
              <uri>model://fire_hose_long_curled/materials/scripts</uri>
              <uri>model://fire_hose_long_curled/materials/textures</uri>
              <name>fire_hose_long_curled/fire_hose_canvas</name>
            </script>
          </material>
        </visual>
        <visual name='sphere'>
          <geometry>
            <sphere>
              <radius>0.025</radius>
            </sphere>
          </geometry>
          <material>
            <script>
              <uri>model://fire_hose_long_curled/materials/scripts</uri>
              <uri>model://fire_hose_long_curled/materials/textures</uri>
              <name>fire_hose_long_curled/fire_hose_canvas</name>
            </script>
          </material>
        </visual>
        <self_collide>0</self_collide>
        <enable_wind>0</enable_wind>
        <kinematic>0</kinematic>
      </link>
      <link name='link_09'>
        <gravity>1</gravity>
        <pose>0.9 -0.254 0 0 0 -3.1415</pose>
        <inertial>
          <mass>0.1</mass>
          <pose>0.1 0 0 0 -0 0</pose>
          <inertia>
            <ixx>0.01</ixx>
            <ixy>0</ixy>
            <ixz>0</ixz>
            <iyy>0.01</iyy>
            <iyz>0</iyz>
            <izz>0.01</izz>
          </inertia>
        </inertial>
        <collision name='collision'>
          <pose>0.1 0 0 0 1.57079 0</pose>
          <geometry>
            <cylinder>
              <length>0.2</length>
              <radius>0.025</radius>
            </cylinder>
          </geometry>
          <surface>
            <contact>
              <ode>
                <min_depth>0.005</min_depth>
              </ode>
            </contact>
            <friction>
              <ode>
                <mu>1</mu>
                <mu2>1</mu2>
              </ode>
              <torsional>
                <ode/>
              </torsional>
            </friction>
            <bounce/>
          </surface>
          <max_contacts>10</max_contacts>
        </collision>
        <visual name='visual'>
          <pose>0.1 0 0 0 1.57079 0</pose>
          <geometry>
            <cylinder>
              <length>0.2</length>
              <radius>0.025</radius>
            </cylinder>
          </geometry>
          <material>
            <script>
              <uri>model://fire_hose_long_curled/materials/scripts</uri>
              <uri>model://fire_hose_long_curled/materials/textures</uri>
              <name>fire_hose_long_curled/fire_hose_canvas</name>
            </script>
          </material>
        </visual>
        <visual name='sphere'>
          <geometry>
            <sphere>
              <radius>0.025</radius>
            </sphere>
          </geometry>
          <material>
            <script>
              <uri>model://fire_hose_long_curled/materials/scripts</uri>
              <uri>model://fire_hose_long_curled/materials/textures</uri>
              <name>fire_hose_long_curled/fire_hose_canvas</name>
            </script>
          </material>
        </visual>
        <self_collide>0</self_collide>
        <enable_wind>0</enable_wind>
        <kinematic>0</kinematic>
      </link>
      <link name='link_10'>
        <gravity>1</gravity>
        <pose>0.7 -0.254 0 0 0 -3.1415</pose>
        <inertial>
          <mass>0.1</mass>
          <pose>0.1 0 0 0 -0 0</pose>
          <inertia>
            <ixx>0.01</ixx>
            <ixy>0</ixy>
            <ixz>0</ixz>
            <iyy>0.01</iyy>
            <iyz>0</iyz>
            <izz>0.01</izz>
          </inertia>
        </inertial>
        <collision name='collision'>
          <pose>0.1 0 0 0 1.57079 0</pose>
          <geometry>
            <cylinder>
              <length>0.2</length>
              <radius>0.025</radius>
            </cylinder>
          </geometry>
          <surface>
            <contact>
              <ode>
                <min_depth>0.005</min_depth>
              </ode>
            </contact>
            <friction>
              <ode>
                <mu>1</mu>
                <mu2>1</mu2>
              </ode>
              <torsional>
                <ode/>
              </torsional>
            </friction>
            <bounce/>
          </surface>
          <max_contacts>10</max_contacts>
        </collision>
        <visual name='visual'>
          <pose>0.1 0 0 0 1.57079 0</pose>
          <geometry>
            <cylinder>
              <length>0.2</length>
              <radius>0.025</radius>
            </cylinder>
          </geometry>
          <material>
            <script>
              <uri>model://fire_hose_long_curled/materials/scripts</uri>
              <uri>model://fire_hose_long_curled/materials/textures</uri>
              <name>fire_hose_long_curled/fire_hose_canvas</name>
            </script>
          </material>
        </visual>
        <visual name='sphere'>
          <geometry>
            <sphere>
              <radius>0.025</radius>
            </sphere>
          </geometry>
          <material>
            <script>
              <uri>model://fire_hose_long_curled/materials/scripts</uri>
              <uri>model://fire_hose_long_curled/materials/textures</uri>
              <name>fire_hose_long_curled/fire_hose_canvas</name>
            </script>
          </material>
        </visual>
        <self_collide>0</self_collide>
        <enable_wind>0</enable_wind>
        <kinematic>0</kinematic>
      </link>
      <link name='link_11'>
        <gravity>1</gravity>
        <pose>0.5 -0.254 0 0 0 -3.1415</pose>
        <inertial>
          <mass>0.1</mass>
          <pose>0.1 0 0 0 -0 0</pose>
          <inertia>
            <ixx>0.01</ixx>
            <ixy>0</ixy>
            <ixz>0</ixz>
            <iyy>0.01</iyy>
            <iyz>0</iyz>
            <izz>0.01</izz>
          </inertia>
        </inertial>
        <collision name='collision'>
          <pose>0.1 0 0 0 1.57079 0</pose>
          <geometry>
            <cylinder>
              <length>0.2</length>
              <radius>0.025</radius>
            </cylinder>
          </geometry>
          <surface>
            <contact>
              <ode>
                <min_depth>0.005</min_depth>
              </ode>
            </contact>
            <friction>
              <ode>
                <mu>1</mu>
                <mu2>1</mu2>
              </ode>
              <torsional>
                <ode/>
              </torsional>
            </friction>
            <bounce/>
          </surface>
          <max_contacts>10</max_contacts>
        </collision>
        <visual name='visual'>
          <pose>0.1 0 0 0 1.57079 0</pose>
          <geometry>
            <cylinder>
              <length>0.2</length>
              <radius>0.025</radius>
            </cylinder>
          </geometry>
          <material>
            <script>
              <uri>model://fire_hose_long_curled/materials/scripts</uri>
              <uri>model://fire_hose_long_curled/materials/textures</uri>
              <name>fire_hose_long_curled/fire_hose_canvas</name>
            </script>
          </material>
        </visual>
        <visual name='sphere'>
          <geometry>
            <sphere>
              <radius>0.025</radius>
            </sphere>
          </geometry>
          <material>
            <script>
              <uri>model://fire_hose_long_curled/materials/scripts</uri>
              <uri>model://fire_hose_long_curled/materials/textures</uri>
              <name>fire_hose_long_curled/fire_hose_canvas</name>
            </script>
          </material>
        </visual>
        <self_collide>0</self_collide>
        <enable_wind>0</enable_wind>
        <kinematic>0</kinematic>
      </link>
      <link name='link_12'>
        <gravity>1</gravity>
        <pose>0.3 -0.254 0 0 0 -3.1415</pose>
        <inertial>
          <mass>0.1</mass>
          <pose>0.1 0 0 0 -0 0</pose>
          <inertia>
            <ixx>0.01</ixx>
            <ixy>0</ixy>
            <ixz>0</ixz>
            <iyy>0.01</iyy>
            <iyz>0</iyz>
            <izz>0.01</izz>
          </inertia>
        </inertial>
        <collision name='collision'>
          <pose>0.1 0 0 0 1.57079 0</pose>
          <geometry>
            <cylinder>
              <length>0.2</length>
              <radius>0.025</radius>
            </cylinder>
          </geometry>
          <surface>
            <contact>
              <ode>
                <min_depth>0.005</min_depth>
              </ode>
            </contact>
            <friction>
              <ode>
                <mu>1</mu>
                <mu2>1</mu2>
              </ode>
              <torsional>
                <ode/>
              </torsional>
            </friction>
            <bounce/>
          </surface>
          <max_contacts>10</max_contacts>
        </collision>
        <visual name='visual'>
          <pose>0.1 0 0 0 1.57079 0</pose>
          <geometry>
            <cylinder>
              <length>0.2</length>
              <radius>0.025</radius>
            </cylinder>
          </geometry>
          <material>
            <script>
              <uri>model://fire_hose_long_curled/materials/scripts</uri>
              <uri>model://fire_hose_long_curled/materials/textures</uri>
              <name>fire_hose_long_curled/fire_hose_canvas</name>
            </script>
          </material>
        </visual>
        <visual name='sphere'>
          <geometry>
            <sphere>
              <radius>0.025</radius>
            </sphere>
          </geometry>
          <material>
            <script>
              <uri>model://fire_hose_long_curled/materials/scripts</uri>
              <uri>model://fire_hose_long_curled/materials/textures</uri>
              <name>fire_hose_long_curled/fire_hose_canvas</name>
            </script>
          </material>
        </visual>
        <self_collide>0</self_collide>
        <enable_wind>0</enable_wind>
        <kinematic>0</kinematic>
      </link>
      <link name='link_13'>
        <gravity>1</gravity>
        <pose>0.1 -0.254 0 0 0 -2.356</pose>
        <inertial>
          <mass>0.1</mass>
          <pose>0.0875 0 0 0 -0 0</pose>
          <inertia>
            <ixx>0.01</ixx>
            <ixy>0</ixy>
            <ixz>0</ixz>
            <iyy>0.01</iyy>
            <iyz>0</iyz>
            <izz>0.01</izz>
          </inertia>
        </inertial>
        <collision name='collision'>
          <pose>0.0875 0 0 0 1.57079 0</pose>
          <geometry>
            <cylinder>
              <length>0.175</length>
              <radius>0.025</radius>
            </cylinder>
          </geometry>
          <surface>
            <contact>
              <ode>
                <min_depth>0.005</min_depth>
              </ode>
            </contact>
            <friction>
              <ode>
                <mu>1</mu>
                <mu2>1</mu2>
              </ode>
              <torsional>
                <ode/>
              </torsional>
            </friction>
            <bounce/>
          </surface>
          <max_contacts>10</max_contacts>
        </collision>
        <visual name='visual'>
          <pose>0.0875 0 0 0 1.57079 0</pose>
          <geometry>
            <cylinder>
              <length>0.175</length>
              <radius>0.025</radius>
            </cylinder>
          </geometry>
          <material>
            <script>
              <uri>model://fire_hose_long_curled/materials/scripts</uri>
              <uri>model://fire_hose_long_curled/materials/textures</uri>
              <name>fire_hose_long_curled/fire_hose_canvas</name>
            </script>
          </material>
        </visual>
        <visual name='sphere'>
          <geometry>
            <sphere>
              <radius>0.025</radius>
            </sphere>
          </geometry>
          <material>
            <script>
              <uri>model://fire_hose_long_curled/materials/scripts</uri>
              <uri>model://fire_hose_long_curled/materials/textures</uri>
              <name>fire_hose_long_curled/fire_hose_canvas</name>
            </script>
          </material>
        </visual>
        <self_collide>0</self_collide>
        <enable_wind>0</enable_wind>
        <kinematic>0</kinematic>
      </link>
      <link name='link_14'>
        <gravity>1</gravity>
        <pose>-0.027 -0.381 0 0 0 -0.785</pose>
        <inertial>
          <mass>0.1</mass>
          <pose>0.0875 0 0 0 -0 0</pose>
          <inertia>
            <ixx>0.01</ixx>
            <ixy>0</ixy>
            <ixz>0</ixz>
            <iyy>0.01</iyy>
            <iyz>0</iyz>
            <izz>0.01</izz>
          </inertia>
        </inertial>
        <collision name='collision'>
          <pose>0.0875 0 0 0 1.57079 0</pose>
          <geometry>
            <cylinder>
              <length>0.175</length>
              <radius>0.025</radius>
            </cylinder>
          </geometry>
          <surface>
            <contact>
              <ode>
                <min_depth>0.005</min_depth>
              </ode>
            </contact>
            <friction>
              <ode>
                <mu>1</mu>
                <mu2>1</mu2>
              </ode>
              <torsional>
                <ode/>
              </torsional>
            </friction>
            <bounce/>
          </surface>
          <max_contacts>10</max_contacts>
        </collision>
        <visual name='visual'>
          <pose>0.0875 0 0 0 1.57079 0</pose>
          <geometry>
            <cylinder>
              <length>0.175</length>
              <radius>0.025</radius>
            </cylinder>
          </geometry>
          <material>
            <script>
              <uri>model://fire_hose_long_curled/materials/scripts</uri>
              <uri>model://fire_hose_long_curled/materials/textures</uri>
              <name>fire_hose_long_curled/fire_hose_canvas</name>
            </script>
          </material>
        </visual>
        <visual name='sphere'>
          <geometry>
            <sphere>
              <radius>0.025</radius>
            </sphere>
          </geometry>
          <material>
            <script>
              <uri>model://fire_hose_long_curled/materials/scripts</uri>
              <uri>model://fire_hose_long_curled/materials/textures</uri>
              <name>fire_hose_long_curled/fire_hose_canvas</name>
            </script>
          </material>
        </visual>
        <self_collide>0</self_collide>
        <enable_wind>0</enable_wind>
        <kinematic>0</kinematic>
      </link>
      <link name='link_15'>
        <gravity>1</gravity>
        <pose>0.1 -0.508 0 0 -0 0</pose>
        <inertial>
          <mass>0.1</mass>
          <pose>0.1 0 0 0 -0 0</pose>
          <inertia>
            <ixx>0.01</ixx>
            <ixy>0</ixy>
            <ixz>0</ixz>
            <iyy>0.01</iyy>
            <iyz>0</iyz>
            <izz>0.01</izz>
          </inertia>
        </inertial>
        <collision name='collision'>
          <pose>0.1 0 0 0 1.57079 0</pose>
          <geometry>
            <cylinder>
              <length>0.2</length>
              <radius>0.025</radius>
            </cylinder>
          </geometry>
          <surface>
            <contact>
              <ode>
                <min_depth>0.005</min_depth>
              </ode>
            </contact>
            <friction>
              <ode>
                <mu>1</mu>
                <mu2>1</mu2>
              </ode>
              <torsional>
                <ode/>
              </torsional>
            </friction>
            <bounce/>
          </surface>
          <max_contacts>10</max_contacts>
        </collision>
        <visual name='visual'>
          <pose>0.1 0 0 0 1.57079 0</pose>
          <geometry>
            <cylinder>
              <length>0.2</length>
              <radius>0.025</radius>
            </cylinder>
          </geometry>
          <material>
            <script>
              <uri>model://fire_hose_long_curled/materials/scripts</uri>
              <uri>model://fire_hose_long_curled/materials/textures</uri>
              <name>fire_hose_long_curled/fire_hose_canvas</name>
            </script>
          </material>
        </visual>
        <visual name='sphere'>
          <geometry>
            <sphere>
              <radius>0.025</radius>
            </sphere>
          </geometry>
          <material>
            <script>
              <uri>model://fire_hose_long_curled/materials/scripts</uri>
              <uri>model://fire_hose_long_curled/materials/textures</uri>
              <name>fire_hose_long_curled/fire_hose_canvas</name>
            </script>
          </material>
        </visual>
        <self_collide>0</self_collide>
        <enable_wind>0</enable_wind>
        <kinematic>0</kinematic>
      </link>
      <link name='link_16'>
        <gravity>1</gravity>
        <pose>0.3 -0.508 0 0 -0 0</pose>
        <inertial>
          <mass>0.1</mass>
          <pose>0.1 0 0 0 -0 0</pose>
          <inertia>
            <ixx>0.01</ixx>
            <ixy>0</ixy>
            <ixz>0</ixz>
            <iyy>0.01</iyy>
            <iyz>0</iyz>
            <izz>0.01</izz>
          </inertia>
        </inertial>
        <collision name='collision'>
          <pose>0.1 0 0 0 1.57079 0</pose>
          <geometry>
            <cylinder>
              <length>0.2</length>
              <radius>0.025</radius>
            </cylinder>
          </geometry>
          <surface>
            <contact>
              <ode>
                <min_depth>0.005</min_depth>
              </ode>
            </contact>
            <friction>
              <ode>
                <mu>1</mu>
                <mu2>1</mu2>
              </ode>
              <torsional>
                <ode/>
              </torsional>
            </friction>
            <bounce/>
          </surface>
          <max_contacts>10</max_contacts>
        </collision>
        <visual name='visual'>
          <pose>0.1 0 0 0 1.57079 0</pose>
          <geometry>
            <cylinder>
              <length>0.2</length>
              <radius>0.025</radius>
            </cylinder>
          </geometry>
          <material>
            <script>
              <uri>model://fire_hose_long_curled/materials/scripts</uri>
              <uri>model://fire_hose_long_curled/materials/textures</uri>
              <name>fire_hose_long_curled/fire_hose_canvas</name>
            </script>
          </material>
        </visual>
        <visual name='sphere'>
          <geometry>
            <sphere>
              <radius>0.025</radius>
            </sphere>
          </geometry>
          <material>
            <script>
              <uri>model://fire_hose_long_curled/materials/scripts</uri>
              <uri>model://fire_hose_long_curled/materials/textures</uri>
              <name>fire_hose_long_curled/fire_hose_canvas</name>
            </script>
          </material>
        </visual>
        <self_collide>0</self_collide>
        <enable_wind>0</enable_wind>
        <kinematic>0</kinematic>
      </link>
      <link name='link_17'>
        <gravity>1</gravity>
        <pose>0.5 -0.508 0 0 -0 0</pose>
        <inertial>
          <mass>0.1</mass>
          <pose>0.1 0 0 0 -0 0</pose>
          <inertia>
            <ixx>0.01</ixx>
            <ixy>0</ixy>
            <ixz>0</ixz>
            <iyy>0.01</iyy>
            <iyz>0</iyz>
            <izz>0.01</izz>
          </inertia>
        </inertial>
        <collision name='collision'>
          <pose>0.1 0 0 0 1.57079 0</pose>
          <geometry>
            <cylinder>
              <length>0.2</length>
              <radius>0.025</radius>
            </cylinder>
          </geometry>
          <surface>
            <contact>
              <ode>
                <min_depth>0.005</min_depth>
              </ode>
            </contact>
            <friction>
              <ode>
                <mu>1</mu>
                <mu2>1</mu2>
              </ode>
              <torsional>
                <ode/>
              </torsional>
            </friction>
            <bounce/>
          </surface>
          <max_contacts>10</max_contacts>
        </collision>
        <visual name='visual'>
          <pose>0.1 0 0 0 1.57079 0</pose>
          <geometry>
            <cylinder>
              <length>0.2</length>
              <radius>0.025</radius>
            </cylinder>
          </geometry>
          <material>
            <script>
              <uri>model://fire_hose_long_curled/materials/scripts</uri>
              <uri>model://fire_hose_long_curled/materials/textures</uri>
              <name>fire_hose_long_curled/fire_hose_canvas</name>
            </script>
          </material>
        </visual>
        <visual name='sphere'>
          <geometry>
            <sphere>
              <radius>0.025</radius>
            </sphere>
          </geometry>
          <material>
            <script>
              <uri>model://fire_hose_long_curled/materials/scripts</uri>
              <uri>model://fire_hose_long_curled/materials/textures</uri>
              <name>fire_hose_long_curled/fire_hose_canvas</name>
            </script>
          </material>
        </visual>
        <self_collide>0</self_collide>
        <enable_wind>0</enable_wind>
        <kinematic>0</kinematic>
      </link>
      <link name='link_18'>
        <gravity>1</gravity>
        <pose>0.7 -0.508 0 0 -0 0</pose>
        <inertial>
          <mass>0.1</mass>
          <pose>0.1 0 0 0 -0 0</pose>
          <inertia>
            <ixx>0.01</ixx>
            <ixy>0</ixy>
            <ixz>0</ixz>
            <iyy>0.01</iyy>
            <iyz>0</iyz>
            <izz>0.01</izz>
          </inertia>
        </inertial>
        <collision name='collision'>
          <pose>0.1 0 0 0 1.57079 0</pose>
          <geometry>
            <cylinder>
              <length>0.2</length>
              <radius>0.025</radius>
            </cylinder>
          </geometry>
          <surface>
            <contact>
              <ode>
                <min_depth>0.005</min_depth>
              </ode>
            </contact>
            <friction>
              <ode>
                <mu>1</mu>
                <mu2>1</mu2>
              </ode>
              <torsional>
                <ode/>
              </torsional>
            </friction>
            <bounce/>
          </surface>
          <max_contacts>10</max_contacts>
        </collision>
        <visual name='visual'>
          <pose>0.1 0 0 0 1.57079 0</pose>
          <geometry>
            <cylinder>
              <length>0.2</length>
              <radius>0.025</radius>
            </cylinder>
          </geometry>
          <material>
            <script>
              <uri>model://fire_hose_long_curled/materials/scripts</uri>
              <uri>model://fire_hose_long_curled/materials/textures</uri>
              <name>fire_hose_long_curled/fire_hose_canvas</name>
            </script>
          </material>
        </visual>
        <visual name='sphere'>
          <geometry>
            <sphere>
              <radius>0.025</radius>
            </sphere>
          </geometry>
          <material>
            <script>
              <uri>model://fire_hose_long_curled/materials/scripts</uri>
              <uri>model://fire_hose_long_curled/materials/textures</uri>
              <name>fire_hose_long_curled/fire_hose_canvas</name>
            </script>
          </material>
        </visual>
        <self_collide>0</self_collide>
        <enable_wind>0</enable_wind>
        <kinematic>0</kinematic>
      </link>
      <link name='link_19'>
        <gravity>1</gravity>
        <pose>0.9 -0.508 0 0 -0 0</pose>
        <inertial>
          <mass>0.1</mass>
          <pose>0.1 0 0 0 -0 0</pose>
          <inertia>
            <ixx>0.01</ixx>
            <ixy>0</ixy>
            <ixz>0</ixz>
            <iyy>0.01</iyy>
            <iyz>0</iyz>
            <izz>0.01</izz>
          </inertia>
        </inertial>
        <collision name='collision'>
          <pose>0.1 0 0 0 1.57079 0</pose>
          <geometry>
            <cylinder>
              <length>0.2</length>
              <radius>0.025</radius>
            </cylinder>
          </geometry>
          <surface>
            <contact>
              <ode>
                <min_depth>0.005</min_depth>
              </ode>
            </contact>
            <friction>
              <ode>
                <mu>1</mu>
                <mu2>1</mu2>
              </ode>
              <torsional>
                <ode/>
              </torsional>
            </friction>
            <bounce/>
          </surface>
          <max_contacts>10</max_contacts>
        </collision>
        <visual name='visual'>
          <pose>0.1 0 0 0 1.57079 0</pose>
          <geometry>
            <cylinder>
              <length>0.2</length>
              <radius>0.025</radius>
            </cylinder>
          </geometry>
          <material>
            <script>
              <uri>model://fire_hose_long_curled/materials/scripts</uri>
              <uri>model://fire_hose_long_curled/materials/textures</uri>
              <name>fire_hose_long_curled/fire_hose_canvas</name>
            </script>
          </material>
        </visual>
        <visual name='sphere'>
          <geometry>
            <sphere>
              <radius>0.025</radius>
            </sphere>
          </geometry>
          <material>
            <script>
              <uri>model://fire_hose_long_curled/materials/scripts</uri>
              <uri>model://fire_hose_long_curled/materials/textures</uri>
              <name>fire_hose_long_curled/fire_hose_canvas</name>
            </script>
          </material>
        </visual>
        <self_collide>0</self_collide>
        <enable_wind>0</enable_wind>
        <kinematic>0</kinematic>
      </link>
      <link name='nozzle'>
        <pose>1.1 -0.508 0 0 -0 3.1415</pose>
        <inertial>
          <mass>0.1</mass>
          <inertia>
            <ixx>0.01</ixx>
            <ixy>0</ixy>
            <ixz>0</ixz>
            <iyy>0.01</iyy>
            <iyz>0</iyz>
            <izz>0.01</izz>
          </inertia>
          <pose>0 0 0 0 -0 0</pose>
        </inertial>
        <collision name='nozzle_collision'>
          <geometry>
            <mesh>
              <scale>1 0.5 0.5</scale>
              <uri>model://fire_hose_long_curled/meshes/nozzle.stl</uri>
            </mesh>
          </geometry>
          <surface>
            <contact>
              <ode>
                <min_depth>0.005</min_depth>
              </ode>
            </contact>
            <friction>
              <ode>
                <mu>1</mu>
                <mu2>1</mu2>
              </ode>
              <torsional>
                <ode/>
              </torsional>
            </friction>
            <bounce/>
          </surface>
          <max_contacts>10</max_contacts>
        </collision>
        <visual name='nozzle_vis'>
          <geometry>
            <mesh>
              <scale>1 0.5 0.5</scale>
              <uri>model://fire_hose_long_curled/meshes/nozzle.stl</uri>
            </mesh>
          </geometry>
        </visual>
        <self_collide>0</self_collide>
        <enable_wind>0</enable_wind>
        <kinematic>0</kinematic>
      </link>
      <joint name='joint_00' type='revolute'>
        <parent>coupling</parent>
        <child>link_00</child>
        <axis>
          <xyz expressed_in='__model__'>1 0 0</xyz>
          <dynamics>
            <damping>1</damping>
            <spring_reference>0</spring_reference>
            <spring_stiffness>0</spring_stiffness>
          </dynamics>
          <limit>
            <lower>-1e+16</lower>
            <upper>1e+16</upper>
          </limit>
        </axis>
        <physics>
          <ode>
            <cfm_damping>1</cfm_damping>
            <limit>
              <cfm>0</cfm>
              <erp>0.2</erp>
            </limit>
          </ode>
        </physics>
      </joint>
      <joint name='joint_01' type='universal'>
        <child>link_01</child>
        <parent>link_00</parent>
        <axis>
          <xyz expressed_in='__model__'>0 1 0</xyz>
          <limit>
            <lower>-1.57</lower>
            <upper>1.57</upper>
          </limit>
          <dynamics>
            <damping>1</damping>
            <spring_reference>0</spring_reference>
            <spring_stiffness>0</spring_stiffness>
          </dynamics>
        </axis>
        <axis2>
          <xyz expressed_in='__model__'>0 0 1</xyz>
          <limit>
            <lower>-1.57</lower>
            <upper>1.57</upper>
          </limit>
          <dynamics>
            <damping>1</damping>
            <spring_reference>0</spring_reference>
            <spring_stiffness>0</spring_stiffness>
          </dynamics>
        </axis2>
        <physics>
          <ode>
            <cfm_damping>1</cfm_damping>
            <limit>
              <cfm>0</cfm>
              <erp>0.2</erp>
            </limit>
          </ode>
        </physics>
      </joint>
      <joint name='joint_02' type='universal'>
        <child>link_02</child>
        <parent>link_01</parent>
        <axis>
          <xyz expressed_in='__model__'>0 1 0</xyz>
          <limit>
            <lower>-1.57</lower>
            <upper>1.57</upper>
          </limit>
          <dynamics>
            <damping>1</damping>
            <spring_reference>0</spring_reference>
            <spring_stiffness>0</spring_stiffness>
          </dynamics>
        </axis>
        <axis2>
          <xyz expressed_in='__model__'>0 0 1</xyz>
          <limit>
            <lower>-1.57</lower>
            <upper>1.57</upper>
          </limit>
          <dynamics>
            <damping>1</damping>
            <spring_reference>0</spring_reference>
            <spring_stiffness>0</spring_stiffness>
          </dynamics>
        </axis2>
        <physics>
          <ode>
            <cfm_damping>1</cfm_damping>
            <limit>
              <cfm>0</cfm>
              <erp>0.2</erp>
            </limit>
          </ode>
        </physics>
      </joint>
      <joint name='joint_03' type='universal'>
        <child>link_03</child>
        <parent>link_02</parent>
        <axis>
          <xyz expressed_in='__model__'>0 1 0</xyz>
          <limit>
            <lower>-1.57</lower>
            <upper>1.57</upper>
          </limit>
          <dynamics>
            <damping>1</damping>
            <spring_reference>0</spring_reference>
            <spring_stiffness>0</spring_stiffness>
          </dynamics>
        </axis>
        <axis2>
          <xyz expressed_in='__model__'>0 0 1</xyz>
          <limit>
            <lower>-1.57</lower>
            <upper>1.57</upper>
          </limit>
          <dynamics>
            <damping>1</damping>
            <spring_reference>0</spring_reference>
            <spring_stiffness>0</spring_stiffness>
          </dynamics>
        </axis2>
        <physics>
          <ode>
            <cfm_damping>1</cfm_damping>
            <limit>
              <cfm>0</cfm>
              <erp>0.2</erp>
            </limit>
          </ode>
        </physics>
      </joint>
      <joint name='joint_04' type='universal'>
        <child>link_04</child>
        <parent>link_03</parent>
        <axis>
          <xyz expressed_in='__model__'>0 1 0</xyz>
          <limit>
            <lower>-1.57</lower>
            <upper>1.57</upper>
          </limit>
          <dynamics>
            <damping>1</damping>
            <spring_reference>0</spring_reference>
            <spring_stiffness>0</spring_stiffness>
          </dynamics>
        </axis>
        <axis2>
          <xyz expressed_in='__model__'>0 0 1</xyz>
          <limit>
            <lower>-1.57</lower>
            <upper>1.57</upper>
          </limit>
          <dynamics>
            <damping>1</damping>
            <spring_reference>0</spring_reference>
            <spring_stiffness>0</spring_stiffness>
          </dynamics>
        </axis2>
        <physics>
          <ode>
            <cfm_damping>1</cfm_damping>
            <limit>
              <cfm>0</cfm>
              <erp>0.2</erp>
            </limit>
          </ode>
        </physics>
      </joint>
      <joint name='joint_05' type='universal'>
        <child>link_05</child>
        <parent>link_04</parent>
        <axis>
          <xyz expressed_in='__model__'>0 1 0</xyz>
          <limit>
            <lower>-1.57</lower>
            <upper>1.57</upper>
          </limit>
          <dynamics>
            <damping>1</damping>
            <spring_reference>0</spring_reference>
            <spring_stiffness>0</spring_stiffness>
          </dynamics>
        </axis>
        <axis2>
          <xyz expressed_in='__model__'>0 0 1</xyz>
          <limit>
            <lower>-1.57</lower>
            <upper>1.57</upper>
          </limit>
          <dynamics>
            <damping>1</damping>
            <spring_reference>0</spring_reference>
            <spring_stiffness>0</spring_stiffness>
          </dynamics>
        </axis2>
        <physics>
          <ode>
            <cfm_damping>1</cfm_damping>
            <limit>
              <cfm>0</cfm>
              <erp>0.2</erp>
            </limit>
          </ode>
        </physics>
      </joint>
      <joint name='joint_06' type='universal'>
        <child>link_06</child>
        <parent>link_05</parent>
        <axis>
          <xyz expressed_in='__model__'>0 0 1</xyz>
          <limit>
            <lower>-0.72</lower>
            <upper>2.35</upper>
          </limit>
          <dynamics>
            <damping>1</damping>
            <spring_reference>0</spring_reference>
            <spring_stiffness>0</spring_stiffness>
          </dynamics>
        </axis>
        <axis2>
          <xyz expressed_in='__model__'>1 1 0</xyz>
          <limit>
            <lower>-1.57</lower>
            <upper>1.57</upper>
          </limit>
          <dynamics>
            <damping>1</damping>
            <spring_reference>0</spring_reference>
            <spring_stiffness>0</spring_stiffness>
          </dynamics>
        </axis2>
        <physics>
          <ode>
            <cfm_damping>1</cfm_damping>
            <limit>
              <cfm>0</cfm>
              <erp>0.2</erp>
            </limit>
          </ode>
        </physics>
      </joint>
      <joint name='joint_07' type='universal'>
        <child>link_07</child>
        <parent>link_06</parent>
        <axis>
          <xyz expressed_in='__model__'>0 0 1</xyz>
          <limit>
            <lower>-0</lower>
            <upper>3</upper>
          </limit>
          <dynamics>
            <damping>1</damping>
            <spring_reference>0</spring_reference>
            <spring_stiffness>0</spring_stiffness>
          </dynamics>
        </axis>
        <axis2>
          <xyz expressed_in='__model__'>-1 1 0</xyz>
          <limit>
            <lower>-1.57</lower>
            <upper>1.57</upper>
          </limit>
          <dynamics>
            <damping>1</damping>
            <spring_reference>0</spring_reference>
            <spring_stiffness>0</spring_stiffness>
          </dynamics>
        </axis2>
        <physics>
          <ode>
            <cfm_damping>1</cfm_damping>
            <limit>
              <cfm>0</cfm>
              <erp>0.2</erp>
            </limit>
          </ode>
        </physics>
      </joint>
      <joint name='joint_08' type='universal'>
        <child>link_08</child>
        <parent>link_07</parent>
        <axis>
          <xyz expressed_in='__model__'>0 1 0</xyz>
          <limit>
            <lower>-1.57</lower>
            <upper>1.57</upper>
          </limit>
          <dynamics>
            <damping>1</damping>
            <spring_reference>0</spring_reference>
            <spring_stiffness>0</spring_stiffness>
          </dynamics>
        </axis>
        <axis2>
          <xyz expressed_in='__model__'>0 0 1</xyz>
          <limit>
            <lower>-0.72</lower>
            <upper>2.35</upper>
          </limit>
          <dynamics>
            <damping>1</damping>
            <spring_reference>0</spring_reference>
            <spring_stiffness>0</spring_stiffness>
          </dynamics>
        </axis2>
        <physics>
          <ode>
            <cfm_damping>1</cfm_damping>
            <limit>
              <cfm>0</cfm>
              <erp>0.2</erp>
            </limit>
          </ode>
        </physics>
      </joint>
      <joint name='joint_09' type='universal'>
        <child>link_09</child>
        <parent>link_08</parent>
        <axis>
          <xyz expressed_in='__model__'>0 1 0</xyz>
          <limit>
            <lower>-1.57</lower>
            <upper>1.57</upper>
          </limit>
          <dynamics>
            <damping>1</damping>
            <spring_reference>0</spring_reference>
            <spring_stiffness>0</spring_stiffness>
          </dynamics>
        </axis>
        <axis2>
          <xyz expressed_in='__model__'>0 0 1</xyz>
          <limit>
            <lower>-1.57</lower>
            <upper>1.57</upper>
          </limit>
          <dynamics>
            <damping>1</damping>
            <spring_reference>0</spring_reference>
            <spring_stiffness>0</spring_stiffness>
          </dynamics>
        </axis2>
        <physics>
          <ode>
            <cfm_damping>1</cfm_damping>
            <limit>
              <cfm>0</cfm>
              <erp>0.2</erp>
            </limit>
          </ode>
        </physics>
      </joint>
      <joint name='joint_10' type='universal'>
        <child>link_10</child>
        <parent>link_09</parent>
        <axis>
          <xyz expressed_in='__model__'>0 1 0</xyz>
          <limit>
            <lower>-1.57</lower>
            <upper>1.57</upper>
          </limit>
          <dynamics>
            <damping>1</damping>
            <spring_reference>0</spring_reference>
            <spring_stiffness>0</spring_stiffness>
          </dynamics>
        </axis>
        <axis2>
          <xyz expressed_in='__model__'>0 0 1</xyz>
          <limit>
            <lower>-1.57</lower>
            <upper>1.57</upper>
          </limit>
          <dynamics>
            <damping>1</damping>
            <spring_reference>0</spring_reference>
            <spring_stiffness>0</spring_stiffness>
          </dynamics>
        </axis2>
        <physics>
          <ode>
            <cfm_damping>1</cfm_damping>
            <limit>
              <cfm>0</cfm>
              <erp>0.2</erp>
            </limit>
          </ode>
        </physics>
      </joint>
      <joint name='joint_11' type='universal'>
        <child>link_11</child>
        <parent>link_10</parent>
        <axis>
          <xyz expressed_in='__model__'>0 1 0</xyz>
          <limit>
            <lower>-1.57</lower>
            <upper>1.57</upper>
          </limit>
          <dynamics>
            <damping>1</damping>
            <spring_reference>0</spring_reference>
            <spring_stiffness>0</spring_stiffness>
          </dynamics>
        </axis>
        <axis2>
          <xyz expressed_in='__model__'>0 0 1</xyz>
          <limit>
            <lower>-1.57</lower>
            <upper>1.57</upper>
          </limit>
          <dynamics>
            <damping>1</damping>
            <spring_reference>0</spring_reference>
            <spring_stiffness>0</spring_stiffness>
          </dynamics>
        </axis2>
        <physics>
          <ode>
            <cfm_damping>1</cfm_damping>
            <limit>
              <cfm>0</cfm>
              <erp>0.2</erp>
            </limit>
          </ode>
        </physics>
      </joint>
      <joint name='joint_12' type='universal'>
        <child>link_12</child>
        <parent>link_11</parent>
        <axis>
          <xyz expressed_in='__model__'>0 1 0</xyz>
          <limit>
            <lower>-1.57</lower>
            <upper>1.57</upper>
          </limit>
          <dynamics>
            <damping>1</damping>
            <spring_reference>0</spring_reference>
            <spring_stiffness>0</spring_stiffness>
          </dynamics>
        </axis>
        <axis2>
          <xyz expressed_in='__model__'>0 0 1</xyz>
          <limit>
            <lower>-1.57</lower>
            <upper>1.57</upper>
          </limit>
          <dynamics>
            <damping>1</damping>
            <spring_reference>0</spring_reference>
            <spring_stiffness>0</spring_stiffness>
          </dynamics>
        </axis2>
        <physics>
          <ode>
            <cfm_damping>1</cfm_damping>
            <limit>
              <cfm>0</cfm>
              <erp>0.2</erp>
            </limit>
          </ode>
        </physics>
      </joint>
      <joint name='joint_13' type='universal'>
        <child>link_13</child>
        <parent>link_12</parent>
        <axis>
          <xyz expressed_in='__model__'>0 0 1</xyz>
          <limit>
            <lower>-2.35</lower>
            <upper>0.72</upper>
          </limit>
          <dynamics>
            <damping>1</damping>
            <spring_reference>0</spring_reference>
            <spring_stiffness>0</spring_stiffness>
          </dynamics>
        </axis>
        <axis2>
          <xyz expressed_in='__model__'>-1 1 0</xyz>
          <limit>
            <lower>-1.57</lower>
            <upper>1.57</upper>
          </limit>
          <dynamics>
            <damping>1</damping>
            <spring_reference>0</spring_reference>
            <spring_stiffness>0</spring_stiffness>
          </dynamics>
        </axis2>
        <physics>
          <ode>
            <cfm_damping>1</cfm_damping>
            <limit>
              <cfm>0</cfm>
              <erp>0.2</erp>
            </limit>
          </ode>
        </physics>
      </joint>
      <joint name='joint_14' type='universal'>
        <child>link_14</child>
        <parent>link_13</parent>
        <axis>
          <xyz expressed_in='__model__'>0 0 1</xyz>
          <limit>
            <lower>-3</lower>
            <upper>0</upper>
          </limit>
          <dynamics>
            <damping>1</damping>
            <spring_reference>0</spring_reference>
            <spring_stiffness>0</spring_stiffness>
          </dynamics>
        </axis>
        <axis2>
          <xyz expressed_in='__model__'>1 1 0</xyz>
          <limit>
            <lower>-1.57</lower>
            <upper>1.57</upper>
          </limit>
          <dynamics>
            <damping>1</damping>
            <spring_reference>0</spring_reference>
            <spring_stiffness>0</spring_stiffness>
          </dynamics>
        </axis2>
        <physics>
          <ode>
            <cfm_damping>1</cfm_damping>
            <limit>
              <cfm>0</cfm>
              <erp>0.2</erp>
            </limit>
          </ode>
        </physics>
      </joint>
      <joint name='joint_15' type='universal'>
        <child>link_15</child>
        <parent>link_14</parent>
        <axis>
          <xyz expressed_in='__model__'>0 0 1</xyz>
          <limit>
            <lower>-2.35</lower>
            <upper>0.72</upper>
          </limit>
          <dynamics>
            <damping>1</damping>
            <spring_reference>0</spring_reference>
            <spring_stiffness>0</spring_stiffness>
          </dynamics>
        </axis>
        <axis2>
          <xyz expressed_in='__model__'>0 1 0</xyz>
          <limit>
            <lower>-1.57</lower>
            <upper>1.57</upper>
          </limit>
          <dynamics>
            <damping>1</damping>
            <spring_reference>0</spring_reference>
            <spring_stiffness>0</spring_stiffness>
          </dynamics>
        </axis2>
        <physics>
          <ode>
            <cfm_damping>1</cfm_damping>
            <limit>
              <cfm>0</cfm>
              <erp>0.2</erp>
            </limit>
          </ode>
        </physics>
      </joint>
      <joint name='joint_16' type='universal'>
        <child>link_16</child>
        <parent>link_15</parent>
        <axis>
          <xyz expressed_in='__model__'>0 1 0</xyz>
          <limit>
            <lower>-1.57</lower>
            <upper>1.57</upper>
          </limit>
          <dynamics>
            <damping>1</damping>
            <spring_reference>0</spring_reference>
            <spring_stiffness>0</spring_stiffness>
          </dynamics>
        </axis>
        <axis2>
          <xyz expressed_in='__model__'>0 0 1</xyz>
          <limit>
            <lower>-1.57</lower>
            <upper>1.57</upper>
          </limit>
          <dynamics>
            <damping>1</damping>
            <spring_reference>0</spring_reference>
            <spring_stiffness>0</spring_stiffness>
          </dynamics>
        </axis2>
        <physics>
          <ode>
            <cfm_damping>1</cfm_damping>
            <limit>
              <cfm>0</cfm>
              <erp>0.2</erp>
            </limit>
          </ode>
        </physics>
      </joint>
      <joint name='joint_17' type='universal'>
        <child>link_17</child>
        <parent>link_16</parent>
        <axis>
          <xyz expressed_in='__model__'>0 1 0</xyz>
          <limit>
            <lower>-1.57</lower>
            <upper>1.57</upper>
          </limit>
          <dynamics>
            <damping>1</damping>
            <spring_reference>0</spring_reference>
            <spring_stiffness>0</spring_stiffness>
          </dynamics>
        </axis>
        <axis2>
          <xyz expressed_in='__model__'>0 0 1</xyz>
          <limit>
            <lower>-1.57</lower>
            <upper>1.57</upper>
          </limit>
          <dynamics>
            <damping>1</damping>
            <spring_reference>0</spring_reference>
            <spring_stiffness>0</spring_stiffness>
          </dynamics>
        </axis2>
        <physics>
          <ode>
            <cfm_damping>1</cfm_damping>
            <limit>
              <cfm>0</cfm>
              <erp>0.2</erp>
            </limit>
          </ode>
        </physics>
      </joint>
      <joint name='joint_18' type='universal'>
        <child>link_18</child>
        <parent>link_17</parent>
        <axis>
          <xyz expressed_in='__model__'>0 1 0</xyz>
          <limit>
            <lower>-1.57</lower>
            <upper>1.57</upper>
          </limit>
          <dynamics>
            <damping>1</damping>
            <spring_reference>0</spring_reference>
            <spring_stiffness>0</spring_stiffness>
          </dynamics>
        </axis>
        <axis2>
          <xyz expressed_in='__model__'>0 0 1</xyz>
          <limit>
            <lower>-1.57</lower>
            <upper>1.57</upper>
          </limit>
          <dynamics>
            <damping>1</damping>
            <spring_reference>0</spring_reference>
            <spring_stiffness>0</spring_stiffness>
          </dynamics>
        </axis2>
        <physics>
          <ode>
            <cfm_damping>1</cfm_damping>
            <limit>
              <cfm>0</cfm>
              <erp>0.2</erp>
            </limit>
          </ode>
        </physics>
      </joint>
      <joint name='joint_19' type='universal'>
        <child>link_19</child>
        <parent>link_18</parent>
        <axis>
          <xyz expressed_in='__model__'>0 1 0</xyz>
          <limit>
            <lower>-1.57</lower>
            <upper>1.57</upper>
          </limit>
          <dynamics>
            <damping>1</damping>
            <spring_reference>0</spring_reference>
            <spring_stiffness>0</spring_stiffness>
          </dynamics>
        </axis>
        <axis2>
          <xyz expressed_in='__model__'>0 0 1</xyz>
          <limit>
            <lower>-1.57</lower>
            <upper>1.57</upper>
          </limit>
          <dynamics>
            <damping>1</damping>
            <spring_reference>0</spring_reference>
            <spring_stiffness>0</spring_stiffness>
          </dynamics>
        </axis2>
        <physics>
          <ode>
            <cfm_damping>1</cfm_damping>
            <limit>
              <cfm>0</cfm>
              <erp>0.2</erp>
            </limit>
          </ode>
        </physics>
      </joint>
      <joint name='joint_20' type='universal'>
        <child>nozzle</child>
        <parent>link_19</parent>
        <axis>
          <xyz expressed_in='__model__'>0 1 0</xyz>
          <limit>
            <lower>-1.57</lower>
            <upper>1.57</upper>
          </limit>
          <dynamics>
            <damping>1</damping>
            <spring_reference>0</spring_reference>
            <spring_stiffness>0</spring_stiffness>
          </dynamics>
        </axis>
        <axis2>
          <xyz expressed_in='__model__'>0 0 1</xyz>
          <limit>
            <lower>-1.57</lower>
            <upper>1.57</upper>
          </limit>
          <dynamics>
            <damping>1</damping>
            <spring_reference>0</spring_reference>
            <spring_stiffness>0</spring_stiffness>
          </dynamics>
        </axis2>
        <physics>
          <ode>
            <cfm_damping>1</cfm_damping>
            <limit>
              <cfm>0</cfm>
              <erp>0.2</erp>
            </limit>
          </ode>
        </physics>
      </joint>
      <joint name='world' type='universal'>
        <child>nozzle</child>
        <parent>world</parent>
        <axis>
          <xyz expressed_in='__model__'>0 1 0</xyz>
          <limit>
            <lower>-1.57</lower>
            <upper>1.57</upper>
          </limit>
          <dynamics>
            <damping>1</damping>
            <spring_reference>0</spring_reference>
            <spring_stiffness>0</spring_stiffness>
          </dynamics>
        </axis>
        <axis2>
          <xyz expressed_in='__model__'>0 0 1</xyz>
          <limit>
            <lower>-1.57</lower>
            <upper>1.57</upper>
          </limit>
          <dynamics>
            <damping>1</damping>
            <spring_reference>0</spring_reference>
            <spring_stiffness>0</spring_stiffness>
          </dynamics>
        </axis2>
        <physics>
          <ode>
            <cfm_damping>1</cfm_damping>
            <limit>
              <cfm>0</cfm>
              <erp>0.2</erp>
            </limit>
          </ode>
        </physics>
      </joint>
    </model>
    <model name='aws_robomaker_warehouse_ShelfD_01'>
      <link name='link'>
        <inertial>
          <mass>30</mass>
          <inertia>
            <ixx>907.144</ixx>
            <ixy>0</ixy>
            <ixz>0</ixz>
            <iyy>104.95</iyy>
            <iyz>0</iyz>
            <izz>824.248</izz>
          </inertia>
        </inertial>
        <collision name='collision'>
          <geometry>
            <mesh>
              <uri>model://aws_robomaker_warehouse_ShelfD_01/meshes/aws_robomaker_warehouse_ShelfD_01_collision.DAE</uri>
              <scale>1 1 1</scale>
            </mesh>
          </geometry>
          <surface>
            <friction>
              <ode>
                <mu>0.2</mu>
                <mu2>0.2</mu2>
                <fdir1>0 0 0</fdir1>
                <slip1>0</slip1>
                <slip2>0</slip2>
              </ode>
              <torsional>
                <ode/>
              </torsional>
            </friction>
            <contact>
              <ode/>
            </contact>
            <bounce/>
          </surface>
          <max_contacts>10</max_contacts>
        </collision>
        <visual name='visual'>
          <geometry>
            <mesh>
              <uri>model://aws_robomaker_warehouse_ShelfD_01/meshes/aws_robomaker_warehouse_ShelfD_01_visual.DAE</uri>
            </mesh>
          </geometry>
          <meta>
            <layer>1</layer>
          </meta>
        </visual>
        <self_collide>0</self_collide>
        <enable_wind>0</enable_wind>
        <kinematic>0</kinematic>
      </link>
      <static>1</static>
      <pose>8.07332 8.40861 0 0 -0 0</pose>
    </model>
    <model name='aws_robomaker_warehouse_ShelfD_01_0'>
      <link name='link'>
        <inertial>
          <mass>30</mass>
          <inertia>
            <ixx>907.144</ixx>
            <ixy>0</ixy>
            <ixz>0</ixz>
            <iyy>104.95</iyy>
            <iyz>0</iyz>
            <izz>824.248</izz>
          </inertia>
        </inertial>
        <collision name='collision'>
          <geometry>
            <mesh>
              <uri>model://aws_robomaker_warehouse_ShelfD_01/meshes/aws_robomaker_warehouse_ShelfD_01_collision.DAE</uri>
              <scale>1 1 1</scale>
            </mesh>
          </geometry>
          <surface>
            <friction>
              <ode>
                <mu>0.2</mu>
                <mu2>0.2</mu2>
                <fdir1>0 0 0</fdir1>
                <slip1>0</slip1>
                <slip2>0</slip2>
              </ode>
              <torsional>
                <ode/>
              </torsional>
            </friction>
            <contact>
              <ode/>
            </contact>
            <bounce/>
          </surface>
          <max_contacts>10</max_contacts>
        </collision>
        <visual name='visual'>
          <geometry>
            <mesh>
              <uri>model://aws_robomaker_warehouse_ShelfD_01/meshes/aws_robomaker_warehouse_ShelfD_01_visual.DAE</uri>
            </mesh>
          </geometry>
          <meta>
            <layer>1</layer>
          </meta>
        </visual>
        <self_collide>0</self_collide>
        <enable_wind>0</enable_wind>
        <kinematic>0</kinematic>
      </link>
      <static>1</static>
      <pose>4.05752 8.45971 0 0 -0 0</pose>
    </model>
    <model name='aws_robomaker_warehouse_ShelfD_01_1'>
      <link name='link'>
        <inertial>
          <mass>30</mass>
          <inertia>
            <ixx>907.144</ixx>
            <ixy>0</ixy>
            <ixz>0</ixz>
            <iyy>104.95</iyy>
            <iyz>0</iyz>
            <izz>824.248</izz>
          </inertia>
        </inertial>
        <collision name='collision'>
          <geometry>
            <mesh>
              <uri>model://aws_robomaker_warehouse_ShelfD_01/meshes/aws_robomaker_warehouse_ShelfD_01_collision.DAE</uri>
              <scale>1 1 1</scale>
            </mesh>
          </geometry>
          <surface>
            <friction>
              <ode>
                <mu>0.2</mu>
                <mu2>0.2</mu2>
                <fdir1>0 0 0</fdir1>
                <slip1>0</slip1>
                <slip2>0</slip2>
              </ode>
              <torsional>
                <ode/>
              </torsional>
            </friction>
            <contact>
              <ode/>
            </contact>
            <bounce/>
          </surface>
          <max_contacts>10</max_contacts>
        </collision>
        <visual name='visual'>
          <geometry>
            <mesh>
              <uri>model://aws_robomaker_warehouse_ShelfD_01/meshes/aws_robomaker_warehouse_ShelfD_01_visual.DAE</uri>
            </mesh>
          </geometry>
          <meta>
            <layer>1</layer>
          </meta>
        </visual>
        <self_collide>0</self_collide>
        <enable_wind>0</enable_wind>
        <kinematic>0</kinematic>
      </link>
      <static>1</static>
      <pose>7.98358 5.32265 0 0 -0 0</pose>
    </model>
    <model name='aws_robomaker_warehouse_ShelfD_01_2'>
      <link name='link'>
        <inertial>
          <mass>30</mass>
          <inertia>
            <ixx>907.144</ixx>
            <ixy>0</ixy>
            <ixz>0</ixz>
            <iyy>104.95</iyy>
            <iyz>0</iyz>
            <izz>824.248</izz>
          </inertia>
        </inertial>
        <collision name='collision'>
          <geometry>
            <mesh>
              <uri>model://aws_robomaker_warehouse_ShelfD_01/meshes/aws_robomaker_warehouse_ShelfD_01_collision.DAE</uri>
              <scale>1 1 1</scale>
            </mesh>
          </geometry>
          <surface>
            <friction>
              <ode>
                <mu>0.2</mu>
                <mu2>0.2</mu2>
                <fdir1>0 0 0</fdir1>
                <slip1>0</slip1>
                <slip2>0</slip2>
              </ode>
              <torsional>
                <ode/>
              </torsional>
            </friction>
            <contact>
              <ode/>
            </contact>
            <bounce/>
          </surface>
          <max_contacts>10</max_contacts>
        </collision>
        <visual name='visual'>
          <geometry>
            <mesh>
              <uri>model://aws_robomaker_warehouse_ShelfD_01/meshes/aws_robomaker_warehouse_ShelfD_01_visual.DAE</uri>
            </mesh>
          </geometry>
          <meta>
            <layer>1</layer>
          </meta>
        </visual>
        <self_collide>0</self_collide>
        <enable_wind>0</enable_wind>
        <kinematic>0</kinematic>
      </link>
      <static>1</static>
      <pose>4.05394 5.4139 0 0 -0 0</pose>
    </model>
    <model name='aws_robomaker_warehouse_ShelfD_01_3'>
      <link name='link'>
        <inertial>
          <mass>30</mass>
          <inertia>
            <ixx>907.144</ixx>
            <ixy>0</ixy>
            <ixz>0</ixz>
            <iyy>104.95</iyy>
            <iyz>0</iyz>
            <izz>824.248</izz>
          </inertia>
        </inertial>
        <collision name='collision'>
          <geometry>
            <mesh>
              <uri>model://aws_robomaker_warehouse_ShelfD_01/meshes/aws_robomaker_warehouse_ShelfD_01_collision.DAE</uri>
              <scale>1 1 1</scale>
            </mesh>
          </geometry>
          <surface>
            <friction>
              <ode>
                <mu>0.2</mu>
                <mu2>0.2</mu2>
                <fdir1>0 0 0</fdir1>
                <slip1>0</slip1>
                <slip2>0</slip2>
              </ode>
              <torsional>
                <ode/>
              </torsional>
            </friction>
            <contact>
              <ode/>
            </contact>
            <bounce/>
          </surface>
          <max_contacts>10</max_contacts>
        </collision>
        <visual name='visual'>
          <geometry>
            <mesh>
              <uri>model://aws_robomaker_warehouse_ShelfD_01/meshes/aws_robomaker_warehouse_ShelfD_01_visual.DAE</uri>
            </mesh>
          </geometry>
          <meta>
            <layer>1</layer>
          </meta>
        </visual>
        <self_collide>0</self_collide>
        <enable_wind>0</enable_wind>
        <kinematic>0</kinematic>
      </link>
      <static>1</static>
      <pose>8.09672 2.4872 0 0 -0 0</pose>
    </model>
    <model name='aws_robomaker_warehouse_ShelfD_01_4'>
      <link name='link'>
        <inertial>
          <mass>30</mass>
          <inertia>
            <ixx>907.144</ixx>
            <ixy>0</ixy>
            <ixz>0</ixz>
            <iyy>104.95</iyy>
            <iyz>0</iyz>
            <izz>824.248</izz>
          </inertia>
        </inertial>
        <collision name='collision'>
          <geometry>
            <mesh>
              <uri>model://aws_robomaker_warehouse_ShelfD_01/meshes/aws_robomaker_warehouse_ShelfD_01_collision.DAE</uri>
              <scale>1 1 1</scale>
            </mesh>
          </geometry>
          <surface>
            <friction>
              <ode>
                <mu>0.2</mu>
                <mu2>0.2</mu2>
                <fdir1>0 0 0</fdir1>
                <slip1>0</slip1>
                <slip2>0</slip2>
              </ode>
              <torsional>
                <ode/>
              </torsional>
            </friction>
            <contact>
              <ode/>
            </contact>
            <bounce/>
          </surface>
          <max_contacts>10</max_contacts>
        </collision>
        <visual name='visual'>
          <geometry>
            <mesh>
              <uri>model://aws_robomaker_warehouse_ShelfD_01/meshes/aws_robomaker_warehouse_ShelfD_01_visual.DAE</uri>
            </mesh>
          </geometry>
          <meta>
            <layer>1</layer>
          </meta>
        </visual>
        <self_collide>0</self_collide>
        <enable_wind>0</enable_wind>
        <kinematic>0</kinematic>
      </link>
      <static>1</static>
      <pose>4.12179 2.48892 0 0 -0 0</pose>
    </model>
    <model name='aws_robomaker_warehouse_ShelfD_01_5'>
      <link name='link'>
        <inertial>
          <mass>30</mass>
          <inertia>
            <ixx>907.144</ixx>
            <ixy>0</ixy>
            <ixz>0</ixz>
            <iyy>104.95</iyy>
            <iyz>0</iyz>
            <izz>824.248</izz>
          </inertia>
        </inertial>
        <collision name='collision'>
          <geometry>
            <mesh>
              <uri>model://aws_robomaker_warehouse_ShelfD_01/meshes/aws_robomaker_warehouse_ShelfD_01_collision.DAE</uri>
              <scale>1 1 1</scale>
            </mesh>
          </geometry>
          <surface>
            <friction>
              <ode>
                <mu>0.2</mu>
                <mu2>0.2</mu2>
                <fdir1>0 0 0</fdir1>
                <slip1>0</slip1>
                <slip2>0</slip2>
              </ode>
              <torsional>
                <ode/>
              </torsional>
            </friction>
            <contact>
              <ode/>
            </contact>
            <bounce/>
          </surface>
          <max_contacts>10</max_contacts>
        </collision>
        <visual name='visual'>
          <geometry>
            <mesh>
              <uri>model://aws_robomaker_warehouse_ShelfD_01/meshes/aws_robomaker_warehouse_ShelfD_01_visual.DAE</uri>
            </mesh>
          </geometry>
          <meta>
            <layer>1</layer>
          </meta>
        </visual>
        <self_collide>0</self_collide>
        <enable_wind>0</enable_wind>
        <kinematic>0</kinematic>
      </link>
      <static>1</static>
      <pose>8.05353 -0.28805 0 0 -0 0</pose>
    </model>
    <model name='aws_robomaker_warehouse_ShelfD_01_6'>
      <link name='link'>
        <inertial>
          <mass>30</mass>
          <inertia>
            <ixx>907.144</ixx>
            <ixy>0</ixy>
            <ixz>0</ixz>
            <iyy>104.95</iyy>
            <iyz>0</iyz>
            <izz>824.248</izz>
          </inertia>
        </inertial>
        <collision name='collision'>
          <geometry>
            <mesh>
              <uri>model://aws_robomaker_warehouse_ShelfD_01/meshes/aws_robomaker_warehouse_ShelfD_01_collision.DAE</uri>
              <scale>1 1 1</scale>
            </mesh>
          </geometry>
          <surface>
            <friction>
              <ode>
                <mu>0.2</mu>
                <mu2>0.2</mu2>
                <fdir1>0 0 0</fdir1>
                <slip1>0</slip1>
                <slip2>0</slip2>
              </ode>
              <torsional>
                <ode/>
              </torsional>
            </friction>
            <contact>
              <ode/>
            </contact>
            <bounce/>
          </surface>
          <max_contacts>10</max_contacts>
        </collision>
        <visual name='visual'>
          <geometry>
            <mesh>
              <uri>model://aws_robomaker_warehouse_ShelfD_01/meshes/aws_robomaker_warehouse_ShelfD_01_visual.DAE</uri>
            </mesh>
          </geometry>
          <meta>
            <layer>1</layer>
          </meta>
        </visual>
        <self_collide>0</self_collide>
        <enable_wind>0</enable_wind>
        <kinematic>0</kinematic>
      </link>
      <static>1</static>
      <pose>4.01037 -0.234414 0 0 -0 0</pose>
    </model>
    <model name='aws_robomaker_warehouse_ShelfD_01_7'>
      <link name='link'>
        <inertial>
          <mass>30</mass>
          <inertia>
            <ixx>907.144</ixx>
            <ixy>0</ixy>
            <ixz>0</ixz>
            <iyy>104.95</iyy>
            <iyz>0</iyz>
            <izz>824.248</izz>
          </inertia>
        </inertial>
        <collision name='collision'>
          <geometry>
            <mesh>
              <uri>model://aws_robomaker_warehouse_ShelfD_01/meshes/aws_robomaker_warehouse_ShelfD_01_collision.DAE</uri>
              <scale>1 1 1</scale>
            </mesh>
          </geometry>
          <surface>
            <friction>
              <ode>
                <mu>0.2</mu>
                <mu2>0.2</mu2>
                <fdir1>0 0 0</fdir1>
                <slip1>0</slip1>
                <slip2>0</slip2>
              </ode>
              <torsional>
                <ode/>
              </torsional>
            </friction>
            <contact>
              <ode/>
            </contact>
            <bounce/>
          </surface>
          <max_contacts>10</max_contacts>
        </collision>
        <visual name='visual'>
          <geometry>
            <mesh>
              <uri>model://aws_robomaker_warehouse_ShelfD_01/meshes/aws_robomaker_warehouse_ShelfD_01_visual.DAE</uri>
            </mesh>
          </geometry>
          <meta>
            <layer>1</layer>
          </meta>
        </visual>
        <self_collide>0</self_collide>
        <enable_wind>0</enable_wind>
        <kinematic>0</kinematic>
      </link>
      <static>1</static>
      <pose>8.01322 -3.11334 0 0 -0 0</pose>
    </model>
    <model name='aws_robomaker_warehouse_ShelfD_01_8'>
      <link name='link'>
        <inertial>
          <mass>30</mass>
          <inertia>
            <ixx>907.144</ixx>
            <ixy>0</ixy>
            <ixz>0</ixz>
            <iyy>104.95</iyy>
            <iyz>0</iyz>
            <izz>824.248</izz>
          </inertia>
        </inertial>
        <collision name='collision'>
          <geometry>
            <mesh>
              <uri>model://aws_robomaker_warehouse_ShelfD_01/meshes/aws_robomaker_warehouse_ShelfD_01_collision.DAE</uri>
              <scale>1 1 1</scale>
            </mesh>
          </geometry>
          <surface>
            <friction>
              <ode>
                <mu>0.2</mu>
                <mu2>0.2</mu2>
                <fdir1>0 0 0</fdir1>
                <slip1>0</slip1>
                <slip2>0</slip2>
              </ode>
              <torsional>
                <ode/>
              </torsional>
            </friction>
            <contact>
              <ode/>
            </contact>
            <bounce/>
          </surface>
          <max_contacts>10</max_contacts>
        </collision>
        <visual name='visual'>
          <geometry>
            <mesh>
              <uri>model://aws_robomaker_warehouse_ShelfD_01/meshes/aws_robomaker_warehouse_ShelfD_01_visual.DAE</uri>
            </mesh>
          </geometry>
          <meta>
            <layer>1</layer>
          </meta>
        </visual>
        <self_collide>0</self_collide>
        <enable_wind>0</enable_wind>
        <kinematic>0</kinematic>
      </link>
      <static>1</static>
      <pose>4.06897 -3.10308 0 0 -0 0</pose>
    </model>
    <model name='aws_robomaker_warehouse_TrashCanC_01'>
      <link name='link'>
        <inertial>
          <mass>1</mass>
          <inertia>
            <ixx>0.2</ixx>
            <ixy>0</ixy>
            <ixz>0</ixz>
            <iyy>0.308</iyy>
            <iyz>0</iyz>
            <izz>0.24</izz>
          </inertia>
        </inertial>
        <collision name='collision'>
          <geometry>
            <mesh>
              <uri>model://aws_robomaker_warehouse_TrashCanC_01/meshes/aws_robomaker_warehouse_TrashCanC_01_collision.DAE</uri>
              <scale>1 1 1</scale>
            </mesh>
          </geometry>
          <surface>
            <friction>
              <ode>
                <mu>0.4</mu>
                <mu2>0.4</mu2>
                <fdir1>0 0 0</fdir1>
                <slip1>0</slip1>
                <slip2>0</slip2>
              </ode>
              <torsional>
                <ode/>
              </torsional>
            </friction>
            <contact>
              <ode/>
            </contact>
            <bounce/>
          </surface>
          <max_contacts>10</max_contacts>
        </collision>
        <visual name='visual'>
          <geometry>
            <mesh>
              <uri>model://aws_robomaker_warehouse_TrashCanC_01/meshes/aws_robomaker_warehouse_TrashCanC_01_visual.DAE</uri>
            </mesh>
          </geometry>
          <meta>
            <layer>1</layer>
          </meta>
        </visual>
        <self_collide>0</self_collide>
        <enable_wind>0</enable_wind>
        <kinematic>0</kinematic>
      </link>
      <static>1</static>
      <pose>-3.947395 -3.409701 0 0 -0 1.57</pose>
    </model>
    
    <model name='aws_robomaker_warehouse_DeskC_01'>
      <link name='link'>
        <inertial>
          <mass>1</mass>
          <inertia>
            <ixx>0.608</ixx>
            <ixy>0</ixy>
            <ixz>0</ixz>
            <iyy>0.476</iyy>
            <iyz>0</iyz>
            <izz>0.542</izz>
          </inertia>
        </inertial>
        <collision name='collision'>
          <geometry>
            <mesh>
              <uri>model://aws_robomaker_warehouse_DeskC_01/meshes/aws_robomaker_warehouse_DeskC_01_collision.DAE</uri>
              <scale>1 1 1</scale>
            </mesh>
          </geometry>
          <surface>
            <friction>
              <ode>
                <mu>0.3</mu>
                <mu2>0.3</mu2>
                <fdir1>0 0 0</fdir1>
                <slip1>0</slip1>
                <slip2>0</slip2>
              </ode>
              <torsional>
                <ode/>
              </torsional>
            </friction>
            <contact>
              <ode/>
            </contact>
            <bounce/>
          </surface>
          <max_contacts>10</max_contacts>
        </collision>
        <visual name='visual'>
          <geometry>
            <mesh>
              <uri>model://aws_robomaker_warehouse_DeskC_01/meshes/aws_robomaker_warehouse_DeskC_01_visual.DAE</uri>
            </mesh>
          </geometry>
          <meta>
            <layer>1</layer>
          </meta>
        </visual>
        <self_collide>0</self_collide>
        <enable_wind>0</enable_wind>
        <kinematic>0</kinematic>
      </link>
      <static>1</static>
      <pose>-4.24526 5.82623 0 0 -0 0</pose>
    </model>
    <model name='desk_chair'>
      <static>1</static>
      <link name='link'>
        <collision name='collision'>
          <pose>0.001581 0.000308 0.612847 0 -0 0</pose>
          <geometry>
            <cylinder>
              <radius>0.33</radius>
              <length>1.23</length>
            </cylinder>
          </geometry>
          <max_contacts>10</max_contacts>
          <surface>
            <contact>
              <ode/>
            </contact>
            <bounce/>
            <friction>
              <torsional>
                <ode/>
              </torsional>
              <ode/>
            </friction>
          </surface>
        </collision>
        <visual name='visual'>
          <geometry>
            <mesh>
              <uri>model://desk_chair/meshes/desk_chair.obj</uri>
              <scale>0.01 0.01 0.01</scale>
            </mesh>
          </geometry>
        </visual>
        <self_collide>0</self_collide>
        <enable_wind>0</enable_wind>
        <kinematic>0</kinematic>
      </link>
      <pose>-3.50506 5.97271 0 0 -0 0</pose>
    </model>
    <model name='servicebot'>
      <link name='link'>
        <collision name='collision'>
          <geometry>
            <mesh>
              <uri>model://servicebot/meshes/servicebot.obj</uri>
              <scale>0.01 0.01 0.01</scale>
            </mesh>
          </geometry>
          <max_contacts>10</max_contacts>
          <surface>
            <contact>
              <ode/>
            </contact>
            <bounce/>
            <friction>
              <torsional>
                <ode/>
              </torsional>
              <ode/>
            </friction>
          </surface>
        </collision>
        <visual name='visual'>
          <geometry>
            <mesh>
              <uri>model://servicebot/meshes/servicebot.obj</uri>
              <scale>0.01 0.01 0.01</scale>
            </mesh>
          </geometry>
        </visual>
        <self_collide>0</self_collide>
        <inertial>
          <pose>0 0 0 0 -0 0</pose>
          <inertia>
            <ixx>1</ixx>
            <ixy>0</ixy>
            <ixz>0</ixz>
            <iyy>1</iyy>
            <iyz>0</iyz>
            <izz>1</izz>
          </inertia>
          <mass>1</mass>
        </inertial>
        <enable_wind>0</enable_wind>
        <kinematic>0</kinematic>
      </link>
      <pose>9.93686 6.82726 0.002543 0.004868 -0 1.62041</pose>
    </model>
    <model name='aws_robomaker_warehouse_PalletJackB_01'>
      <link name='link'>
        <inertial>
          <mass>2</mass>
          <inertia>
            <ixx>0.277</ixx>
            <ixy>0</ixy>
            <ixz>0</ixz>
            <iyy>0.452</iyy>
            <iyz>0</iyz>
            <izz>0.268</izz>
          </inertia>
        </inertial>
        <collision name='collision'>
          <geometry>
            <mesh>
              <uri>model://aws_robomaker_warehouse_PalletJackB_01/meshes/aws_robomaker_warehouse_PalletJackB_01_collision.DAE</uri>
              <scale>1 1 1</scale>
            </mesh>
          </geometry>
          <surface>
            <friction>
              <ode>
                <mu>0.2</mu>
                <mu2>0.2</mu2>
                <fdir1>0 0 0</fdir1>
                <slip1>0</slip1>
                <slip2>0</slip2>
              </ode>
              <torsional>
                <ode/>
              </torsional>
            </friction>
            <contact>
              <ode/>
            </contact>
            <bounce/>
          </surface>
          <max_contacts>10</max_contacts>
        </collision>
        <visual name='visual'>
          <geometry>
            <mesh>
              <uri>model://aws_robomaker_warehouse_PalletJackB_01/meshes/aws_robomaker_warehouse_PalletJackB_01_visual.DAE</uri>
            </mesh>
          </geometry>
          <meta>
            <layer>1</layer>
          </meta>
        </visual>
        <self_collide>0</self_collide>
        <enable_wind>0</enable_wind>
        <kinematic>0</kinematic>
      </link>
      <static>1</static>
      <pose>3.07729 7.45025 0 0 -0 0</pose>
    </model>
    <model name='aws_robomaker_warehouse_PalletJackB_01_0'>
      <link name='link'>
        <inertial>
          <mass>2</mass>
          <inertia>
            <ixx>0.277</ixx>
            <ixy>0</ixy>
            <ixz>0</ixz>
            <iyy>0.452</iyy>
            <iyz>0</iyz>
            <izz>0.268</izz>
          </inertia>
        </inertial>
        <collision name='collision'>
          <geometry>
            <mesh>
              <uri>model://aws_robomaker_warehouse_PalletJackB_01/meshes/aws_robomaker_warehouse_PalletJackB_01_collision.DAE</uri>
              <scale>1 1 1</scale>
            </mesh>
          </geometry>
          <surface>
            <friction>
              <ode>
                <mu>0.2</mu>
                <mu2>0.2</mu2>
                <fdir1>0 0 0</fdir1>
                <slip1>0</slip1>
                <slip2>0</slip2>
              </ode>
              <torsional>
                <ode/>
              </torsional>
            </friction>
            <contact>
              <ode/>
            </contact>
            <bounce/>
          </surface>
          <max_contacts>10</max_contacts>
        </collision>
        <visual name='visual'>
          <geometry>
            <mesh>
              <uri>model://aws_robomaker_warehouse_PalletJackB_01/meshes/aws_robomaker_warehouse_PalletJackB_01_visual.DAE</uri>
            </mesh>
          </geometry>
          <meta>
            <layer>1</layer>
          </meta>
        </visual>
        <self_collide>0</self_collide>
        <enable_wind>0</enable_wind>
        <kinematic>0</kinematic>
      </link>
      <static>1</static>
      <pose>2.94773 3.98068 0 0 -0 0</pose>
    </model>
    <model name='aws_robomaker_warehouse_PalletJackB_01_1'>
      <link name='link'>
        <inertial>
          <mass>2</mass>
          <inertia>
            <ixx>0.277</ixx>
            <ixy>0</ixy>
            <ixz>0</ixz>
            <iyy>0.452</iyy>
            <iyz>0</iyz>
            <izz>0.268</izz>
          </inertia>
        </inertial>
        <collision name='collision'>
          <geometry>
            <mesh>
              <uri>model://aws_robomaker_warehouse_PalletJackB_01/meshes/aws_robomaker_warehouse_PalletJackB_01_collision.DAE</uri>
              <scale>1 1 1</scale>
            </mesh>
          </geometry>
          <surface>
            <friction>
              <ode>
                <mu>0.2</mu>
                <mu2>0.2</mu2>
                <fdir1>0 0 0</fdir1>
                <slip1>0</slip1>
                <slip2>0</slip2>
              </ode>
              <torsional>
                <ode/>
              </torsional>
            </friction>
            <contact>
              <ode/>
            </contact>
            <bounce/>
          </surface>
          <max_contacts>10</max_contacts>
        </collision>
        <visual name='visual'>
          <geometry>
            <mesh>
              <uri>model://aws_robomaker_warehouse_PalletJackB_01/meshes/aws_robomaker_warehouse_PalletJackB_01_visual.DAE</uri>
            </mesh>
          </geometry>
          <meta>
            <layer>1</layer>
          </meta>
        </visual>
        <self_collide>0</self_collide>
        <enable_wind>0</enable_wind>
        <kinematic>0</kinematic>
      </link>
      <static>1</static>
      <pose>2.85886 0.934213 0 0 -0 0</pose>
    </model>
    <model name='Charging Dock'>
      <static>1</static>
      <link name='docking_station_link'>
        <pose>0 0 0.25 0 -0 0</pose>
        <inertial>
          <mass>1</mass>
          <inertia>
            <ixx>0.083</ixx>
            <ixy>0</ixy>
            <ixz>0</ixz>
            <iyy>0.083</iyy>
            <iyz>0</iyz>
            <izz>0.083</izz>
          </inertia>
        </inertial>
        <collision name='docking_station_collision'>
          <geometry>
            <box>
              <size>0.35 0.35 0.5</size>
            </box>
          </geometry>
          <max_contacts>10</max_contacts>
          <surface>
            <contact>
              <ode/>
            </contact>
            <bounce/>
            <friction>
              <torsional>
                <ode/>
              </torsional>
              <ode/>
            </friction>
          </surface>
        </collision>
        <visual name='docking_station_visual'>
          <geometry>
            <box>
              <size>0.35 0.35 0.5</size>
            </box>
          </geometry>
          <material>
            <ambient>0.1 0.1 0.1 1</ambient>
            <diffuse>0.1 0.1 0.1 1</diffuse>
            <specular>0 0 0 0</specular>
            <emissive>0 0 0 1</emissive>
          </material>
        </visual>
        <self_collide>0</self_collide>
        <enable_wind>0</enable_wind>
        <kinematic>0</kinematic>
      </link>
      <link name='artag_link'>
        <pose>0.18 0 0.1 0 -0 0</pose>
        <visual name='visual'>
          <geometry>
            <mesh>
              <uri>model://charging_dock/meshes/Marker0.dae</uri>
              <scale>0.4 0.4 0.4</scale>
            </mesh>
          </geometry>
        </visual>
        <self_collide>0</self_collide>
        <enable_wind>0</enable_wind>
        <kinematic>0</kinematic>
      </link>
      <pose>-4.44907 -2.04806 0 0 -0 0</pose>
    </model>
    <model name='StorageRackCoverOpen'>
      <link name='link'>
        <pose>0 0 0 0 -0 0</pose>
        <visual name='visual'>
          <geometry>
            <mesh>
              <uri>model://StorageRackCoverOpen/meshes/StorageRackCoverOpen.obj</uri>
            </mesh>
          </geometry>
        </visual>
        <collision name='collision'>
          <geometry>
            <mesh>
              <uri>model://StorageRackCoverOpen/meshes/StorageRackCoverOpen.obj</uri>
            </mesh>
          </geometry>
          <max_contacts>10</max_contacts>
          <surface>
            <contact>
              <ode/>
            </contact>
            <bounce/>
            <friction>
              <torsional>
                <ode/>
              </torsional>
              <ode/>
            </friction>
          </surface>
        </collision>
        <self_collide>0</self_collide>
        <inertial>
          <pose>0 0 0 0 -0 0</pose>
          <inertia>
            <ixx>1</ixx>
            <ixy>0</ixy>
            <ixz>0</ixz>
            <iyy>1</iyy>
            <iyz>0</iyz>
            <izz>1</izz>
          </inertia>
          <mass>1</mass>
        </inertial>
        <enable_wind>0</enable_wind>
        <kinematic>0</kinematic>
      </link>
      <pose>-0.209923 8.74282 0 0 -0 0</pose>
    </model>
    <model name='aws_robomaker_warehouse_PalletJackB_01_2'>
      <link name='link'>
        <inertial>
          <mass>2</mass>
          <inertia>
            <ixx>0.277</ixx>
            <ixy>0</ixy>
            <ixz>0</ixz>
            <iyy>0.452</iyy>
            <iyz>0</iyz>
            <izz>0.268</izz>
          </inertia>
        </inertial>
        <collision name='collision'>
          <geometry>
            <mesh>
              <uri>model://aws_robomaker_warehouse_PalletJackB_01/meshes/aws_robomaker_warehouse_PalletJackB_01_collision.DAE</uri>
              <scale>1 1 1</scale>
            </mesh>
          </geometry>
          <surface>
            <friction>
              <ode>
                <mu>0.2</mu>
                <mu2>0.2</mu2>
                <fdir1>0 0 0</fdir1>
                <slip1>0</slip1>
                <slip2>0</slip2>
              </ode>
              <torsional>
                <ode/>
              </torsional>
            </friction>
            <contact>
              <ode/>
            </contact>
            <bounce/>
          </surface>
          <max_contacts>10</max_contacts>
        </collision>
        <visual name='visual'>
          <geometry>
            <mesh>
              <uri>model://aws_robomaker_warehouse_PalletJackB_01/meshes/aws_robomaker_warehouse_PalletJackB_01_visual.DAE</uri>
            </mesh>
          </geometry>
          <meta>
            <layer>1</layer>
          </meta>
        </visual>
        <self_collide>0</self_collide>
        <enable_wind>0</enable_wind>
        <kinematic>0</kinematic>
      </link>
      <static>1</static>
      <pose>2.96852 -1.89547 0 0 -0 0</pose>
    </model>
    <model name='Charging Dock_0'>
      <static>1</static>
      <link name='docking_station_link'>
        <pose>0 0 0.25 0 -0 0</pose>
        <inertial>
          <mass>1</mass>
          <inertia>
            <ixx>0.083</ixx>
            <ixy>0</ixy>
            <ixz>0</ixz>
            <iyy>0.083</iyy>
            <iyz>0</iyz>
            <izz>0.083</izz>
          </inertia>
        </inertial>
        <collision name='docking_station_collision'>
          <geometry>
            <box>
              <size>0.35 0.35 0.5</size>
            </box>
          </geometry>
          <max_contacts>10</max_contacts>
          <surface>
            <contact>
              <ode/>
            </contact>
            <bounce/>
            <friction>
              <torsional>
                <ode/>
              </torsional>
              <ode/>
            </friction>
          </surface>
        </collision>
        <visual name='docking_station_visual'>
          <geometry>
            <box>
              <size>0.35 0.35 0.5</size>
            </box>
          </geometry>
          <material>
            <ambient>0.1 0.1 0.1 1</ambient>
            <diffuse>0.1 0.1 0.1 1</diffuse>
            <specular>0 0 0 0</specular>
            <emissive>0 0 0 1</emissive>
          </material>
        </visual>
        <self_collide>0</self_collide>
        <enable_wind>0</enable_wind>
        <kinematic>0</kinematic>
      </link>
      <link name='artag_link'>
        <pose>0.18 0 0.1 0 -0 0</pose>
        <visual name='visual'>
          <geometry>
            <mesh>
              <uri>model://charging_dock/meshes/Marker0.dae</uri>
              <scale>0.4 0.4 0.4</scale>
            </mesh>
          </geometry>
        </visual>
        <self_collide>0</self_collide>
        <enable_wind>0</enable_wind>
        <kinematic>0</kinematic>
      </link>
      <pose>9.63587 1.17313 0.1 0 -0 3.08392</pose>
    </model>
    <model name='aws_robomaker_warehouse_ClutteringC_01'>
      <link name='link'>
        <inertial>
          <mass>1</mass>
          <inertia>
            <ixx>1.558</ixx>
            <ixy>0</ixy>
            <ixz>0</ixz>
            <iyy>1.821</iyy>
            <iyz>0</iyz>
            <izz>1.892</izz>
          </inertia>
        </inertial>
        <collision name='collision'>
          <geometry>
            <mesh>
              <uri>model://aws_robomaker_warehouse_ClutteringC_01/meshes/aws_robomaker_warehouse_ClutteringC_01_collision.DAE</uri>
              <scale>1 1 1</scale>
            </mesh>
          </geometry>
          <surface>
            <friction>
              <ode>
                <mu>0.6</mu>
                <mu2>0.6</mu2>
                <fdir1>0 0 0</fdir1>
                <slip1>0</slip1>
                <slip2>0</slip2>
              </ode>
              <torsional>
                <coefficient>1</coefficient>
                <patch_radius>0</patch_radius>
                <surface_radius>0</surface_radius>
                <use_patch_radius>1</use_patch_radius>
                <ode>
                  <slip>0</slip>
                </ode>
              </torsional>
            </friction>
            <contact>
              <ode/>
            </contact>
            <bounce/>
          </surface>
          <max_contacts>10</max_contacts>
        </collision>
        <visual name='visual'>
          <geometry>
            <mesh>
              <uri>model://aws_robomaker_warehouse_ClutteringC_01/meshes/aws_robomaker_warehouse_ClutteringC_01_visual.DAE</uri>
            </mesh>
          </geometry>
          <meta>
            <layer>1</layer>
          </meta>
        </visual>
        <self_collide>0</self_collide>
        <enable_wind>0</enable_wind>
        <kinematic>0</kinematic>
      </link>
      <static>1</static>
      <pose>-3.46996 3.14535 0 0 -0 0</pose>
    </model>
    <model name='aws_robomaker_warehouse_ClutteringA_01'>
      <link name='link'>
        <inertial>
          <mass>2</mass>
          <inertia>
            <ixx>0.841</ixx>
            <ixy>0</ixy>
            <ixz>0</ixz>
            <iyy>0.954</iyy>
            <iyz>0</iyz>
            <izz>1.422</izz>
          </inertia>
        </inertial>
        <collision name='collision'>
          <geometry>
            <mesh>
              <uri>model://aws_robomaker_warehouse_ClutteringA_01/meshes/aws_robomaker_warehouse_ClutteringA_01_collision.DAE</uri>
              <scale>1 1 1</scale>
            </mesh>
          </geometry>
          <surface>
            <friction>
              <ode>
                <mu>0.6</mu>
                <mu2>0.6</mu2>
                <fdir1>0 0 0</fdir1>
                <slip1>0</slip1>
                <slip2>0</slip2>
              </ode>
              <torsional>
                <coefficient>1</coefficient>
                <patch_radius>0</patch_radius>
                <surface_radius>0</surface_radius>
                <use_patch_radius>1</use_patch_radius>
                <ode>
                  <slip>0</slip>
                </ode>
              </torsional>
            </friction>
            <contact>
              <ode/>
            </contact>
            <bounce/>
          </surface>
          <max_contacts>10</max_contacts>
        </collision>
        <visual name='visual'>
          <geometry>
            <mesh>
              <uri>model://aws_robomaker_warehouse_ClutteringA_01/meshes/aws_robomaker_warehouse_ClutteringA_01_visual.DAE</uri>
            </mesh>
          </geometry>
          <meta>
            <layer>1</layer>
          </meta>
        </visual>
        <self_collide>0</self_collide>
        <enable_wind>0</enable_wind>
        <kinematic>0</kinematic>
      </link>
      <static>1</static>
      <pose>-3.4418 1.07777 0 0 -0 0</pose>
    </model>
    <model name='aws_robomaker_warehouse_ClutteringD_01'>
      <link name='link'>
        <inertial>
          <mass>1</mass>
          <inertia>
            <ixx>1.558</ixx>
            <ixy>0</ixy>
            <ixz>0</ixz>
            <iyy>1.821</iyy>
            <iyz>0</iyz>
            <izz>1.892</izz>
          </inertia>
        </inertial>
        <collision name='collision'>
          <geometry>
            <mesh>
              <uri>model://aws_robomaker_warehouse_ClutteringD_01/meshes/aws_robomaker_warehouse_ClutteringD_01_collision.DAE</uri>
              <scale>1 1 1</scale>
            </mesh>
          </geometry>
          <surface>
            <friction>
              <ode>
                <mu>0.6</mu>
                <mu2>0.6</mu2>
                <fdir1>0 0 0</fdir1>
                <slip1>0</slip1>
                <slip2>0</slip2>
              </ode>
              <torsional>
                <coefficient>1</coefficient>
                <patch_radius>0</patch_radius>
                <surface_radius>0</surface_radius>
                <use_patch_radius>1</use_patch_radius>
                <ode>
                  <slip>0</slip>
                </ode>
              </torsional>
            </friction>
            <contact>
              <ode/>
            </contact>
            <bounce/>
          </surface>
          <max_contacts>10</max_contacts>
        </collision>
        <visual name='visual'>
          <geometry>
            <mesh>
              <uri>model://aws_robomaker_warehouse_ClutteringD_01/meshes/aws_robomaker_warehouse_ClutteringD_01_visual.DAE</uri>
            </mesh>
          </geometry>
          <meta>
            <layer>1</layer>
          </meta>
        </visual>
        <self_collide>0</self_collide>
        <enable_wind>0</enable_wind>
        <kinematic>0</kinematic>
      </link>
      <static>1</static>
      <pose>-2.05694 3.11547 0 0 -0 0</pose>
    </model>
    <model name='aws_robomaker_warehouse_ClutteringA_01_0'>
      <link name='link'>
        <inertial>
          <mass>2</mass>
          <inertia>
            <ixx>0.841</ixx>
            <ixy>0</ixy>
            <ixz>0</ixz>
            <iyy>0.954</iyy>
            <iyz>0</iyz>
            <izz>1.422</izz>
          </inertia>
        </inertial>
        <collision name='collision'>
          <geometry>
            <mesh>
              <uri>model://aws_robomaker_warehouse_ClutteringA_01/meshes/aws_robomaker_warehouse_ClutteringA_01_collision.DAE</uri>
              <scale>1 1 1</scale>
            </mesh>
          </geometry>
          <surface>
            <friction>
              <ode>
                <mu>0.6</mu>
                <mu2>0.6</mu2>
                <fdir1>0 0 0</fdir1>
                <slip1>0</slip1>
                <slip2>0</slip2>
              </ode>
              <torsional>
                <coefficient>1</coefficient>
                <patch_radius>0</patch_radius>
                <surface_radius>0</surface_radius>
                <use_patch_radius>1</use_patch_radius>
                <ode>
                  <slip>0</slip>
                </ode>
              </torsional>
            </friction>
            <contact>
              <ode/>
            </contact>
            <bounce/>
          </surface>
          <max_contacts>10</max_contacts>
        </collision>
        <visual name='visual'>
          <geometry>
            <mesh>
              <uri>model://aws_robomaker_warehouse_ClutteringA_01/meshes/aws_robomaker_warehouse_ClutteringA_01_visual.DAE</uri>
            </mesh>
          </geometry>
          <meta>
            <layer>1</layer>
          </meta>
        </visual>
        <self_collide>0</self_collide>
        <enable_wind>0</enable_wind>
        <kinematic>0</kinematic>
      </link>
      <static>1</static>
      <pose>-1.45616 1.56404 0 0 -0 0</pose>
    </model>
    <state world_name='default'>
      <sim_time>569 317000000</sim_time>
      <real_time>238 188070845</real_time>
      <wall_time>1733153166 687882303</wall_time>
      <iterations>132929</iterations>
      <model name='Charging Dock'>
        <pose>-4.44907 -2.04806 0 0 -0 0</pose>
        <scale>1 1 1</scale>
        <link name='artag_link'>
          <pose>-4.26907 -2.04806 0.1 0 -0 0</pose>
          <velocity>0 0 0 0 -0 0</velocity>
          <acceleration>0 0 0 0 -0 0</acceleration>
          <wrench>0 0 0 0 -0 0</wrench>
        </link>
        <link name='docking_station_link'>
          <pose>-4.44907 -2.04806 0.25 0 -0 0</pose>
          <velocity>0 0 0 0 -0 0</velocity>
          <acceleration>0 0 0 0 -0 0</acceleration>
          <wrench>0 0 0 0 -0 0</wrench>
        </link>
      </model>
        <model name='Charging Dock_0'>
        <pose>9.63587 1.17313 0.1 0 -0 3.08392</pose>
        <scale>1 1 1</scale>
        <link name='artag_link'>
          <pose>-4.26907 -2.04806 0.1 0 -0 0</pose>
          <velocity>0 0 0 0 -0 0</velocity>
          <acceleration>0 0 0 0 -0 0</acceleration>
          <wrench>0 0 0 0 -0 0</wrench>
        </link>
        <link name='docking_station_link'>
          <pose>9.81557 1.16275 0.25 0 -0 1.53268</pose>
          <velocity>0 0 0 0 -0 0</velocity>
          <acceleration>0 0 0 0 -0 0</acceleration>
          <wrench>0 0 0 0 -0 0</wrench>
        </link>
      </model>
      <model name='StorageRackCoverOpen'>
        <pose>-0.214305 8.68732 -0 -0 1e-06 -0.010782</pose>
        <scale>1 1 1</scale>
        <link name='link'>
          <pose>-0.214305 8.68732 -0 -0 1e-06 -0.010782</pose>
          <velocity>0 0 0 0 -0 0</velocity>
          <acceleration>8e-06 0 0.743918 0.13701 0.148211 -1e-06</acceleration>
          <wrench>8e-06 0 0.743918 0 -0 0</wrench>
        </link>
      </model>
      <model name='VendingMachine'>
        <pose>-4.2473 -4.8209 -0 1e-06 -0 0</pose>
        <scale>1 1 1</scale>
        <link name='body'>
          <pose>-4.2473 -4.8209 -0 1e-06 -0 0</pose>
          <velocity>0 0 0 0 -0 0</velocity>
          <acceleration>-0 -2e-06 -0.205234 -2.15032 -0.048502 -0</acceleration>
          <wrench>-0 -2e-06 -0.205234 0 -0 0</wrench>
        </link>
      </model>
      <model name='aws_robomaker_warehouse_ClutteringA_01'>
        <pose>-3.4418 1.07777 0 0 -0 0</pose>
        <scale>1 1 1</scale>
        <link name='link'>
          <pose>-3.4418 1.07777 0 0 -0 0</pose>
          <velocity>0 0 0 0 -0 0</velocity>
          <acceleration>0 0 0 0 -0 0</acceleration>
          <wrench>0 0 0 0 -0 0</wrench>
        </link>
      </model>
      <model name='aws_robomaker_warehouse_ClutteringA_01_0'>
        <pose>-1.45616 1.56404 0 0 -0 0</pose>
        <scale>1 1 1</scale>
        <link name='link'>
          <pose>-1.45616 1.56404 0 0 -0 0</pose>
          <velocity>0 0 0 0 -0 0</velocity>
          <acceleration>0 0 0 0 -0 0</acceleration>
          <wrench>0 0 0 0 -0 0</wrench>
        </link>
      </model>
      <model name='aws_robomaker_warehouse_ClutteringC_01'>
        <pose>-3.46996 3.14535 0 0 -0 0</pose>
        <scale>1 1 1</scale>
        <link name='link'>
          <pose>-3.46996 3.14535 0 0 -0 0</pose>
          <velocity>0 0 0 0 -0 0</velocity>
          <acceleration>0 0 0 0 -0 0</acceleration>
          <wrench>0 0 0 0 -0 0</wrench>
        </link>
      </model>
      <model name='aws_robomaker_warehouse_ClutteringD_01'>
        <pose>-2.05694 3.11547 0 0 -0 0</pose>
        <scale>1 1 1</scale>
        <link name='link'>
          <pose>-2.05694 3.11547 0 0 -0 0</pose>
          <velocity>0 0 0 0 -0 0</velocity>
          <acceleration>0 0 0 0 -0 0</acceleration>
          <wrench>0 0 0 0 -0 0</wrench>
        </link>
      </model>
      <model name='aws_robomaker_warehouse_DeskC_01'>
        <pose>-4.24526 5.82623 0 0 -0 0</pose>
        <scale>1 1 1</scale>
        <link name='link'>
          <pose>-4.24526 5.82623 0 0 -0 0</pose>
          <velocity>0 0 0 0 -0 0</velocity>
          <acceleration>0 0 0 0 -0 0</acceleration>
          <wrench>0 0 0 0 -0 0</wrench>
        </link>
      </model>
      <model name='aws_robomaker_warehouse_PalletJackB_01'>
        <pose>3.07729 7.45025 0 0 -0 0</pose>
        <scale>1 1 1</scale>
        <link name='link'>
          <pose>3.07729 7.45025 0 0 -0 0</pose>
          <velocity>0 0 0 0 -0 0</velocity>
          <acceleration>0 0 0 0 -0 0</acceleration>
          <wrench>0 0 0 0 -0 0</wrench>
        </link>
      </model>
      <model name='aws_robomaker_warehouse_PalletJackB_01_0'>
        <pose>2.94773 3.98068 0 0 -0 0</pose>
        <scale>1 1 1</scale>
        <link name='link'>
          <pose>2.94773 3.98068 0 0 -0 0</pose>
          <velocity>0 0 0 0 -0 0</velocity>
          <acceleration>0 0 0 0 -0 0</acceleration>
          <wrench>0 0 0 0 -0 0</wrench>
        </link>
      </model>
      <model name='aws_robomaker_warehouse_PalletJackB_01_1'>
        <pose>2.85886 0.934213 0 0 -0 0</pose>
        <scale>1 1 1</scale>
        <link name='link'>
          <pose>2.85886 0.934213 0 0 -0 0</pose>
          <velocity>0 0 0 0 -0 0</velocity>
          <acceleration>0 0 0 0 -0 0</acceleration>
          <wrench>0 0 0 0 -0 0</wrench>
        </link>
      </model>
      <model name='aws_robomaker_warehouse_PalletJackB_01_2'>
        <pose>2.96852 -1.89547 0 0 -0 0</pose>
        <scale>1 1 1</scale>
        <link name='link'>
          <pose>2.96852 -1.89547 0 0 -0 0</pose>
          <velocity>0 0 0 0 -0 0</velocity>
          <acceleration>0 0 0 0 -0 0</acceleration>
          <wrench>0 0 0 0 -0 0</wrench>
        </link>
      </model>
      <model name='aws_robomaker_warehouse_ShelfD_01'>
        <pose>8.07332 8.40861 0 0 -0 0</pose>
        <scale>1 1 1</scale>
        <link name='link'>
          <pose>8.07332 8.40861 0 0 -0 0</pose>
          <velocity>0 0 0 0 -0 0</velocity>
          <acceleration>0 0 0 0 -0 0</acceleration>
          <wrench>0 0 0 0 -0 0</wrench>
        </link>
      </model>
      <model name='aws_robomaker_warehouse_ShelfD_01_0'>
        <pose>4.05752 8.45971 0 0 -0 0</pose>
        <scale>1 1 1</scale>
        <link name='link'>
          <pose>4.05752 8.45971 0 0 -0 0</pose>
          <velocity>0 0 0 0 -0 0</velocity>
          <acceleration>0 0 0 0 -0 0</acceleration>
          <wrench>0 0 0 0 -0 0</wrench>
        </link>
      </model>
      <model name='aws_robomaker_warehouse_ShelfD_01_1'>
        <pose>7.98358 5.32265 0 0 -0 0</pose>
        <scale>1 1 1</scale>
        <link name='link'>
          <pose>7.98358 5.32265 0 0 -0 0</pose>
          <velocity>0 0 0 0 -0 0</velocity>
          <acceleration>0 0 0 0 -0 0</acceleration>
          <wrench>0 0 0 0 -0 0</wrench>
        </link>
      </model>
      <model name='aws_robomaker_warehouse_ShelfD_01_2'>
        <pose>4.05394 5.4139 0 0 -0 0</pose>
        <scale>1 1 1</scale>
        <link name='link'>
          <pose>4.05394 5.4139 0 0 -0 0</pose>
          <velocity>0 0 0 0 -0 0</velocity>
          <acceleration>0 0 0 0 -0 0</acceleration>
          <wrench>0 0 0 0 -0 0</wrench>
        </link>
      </model>
      <model name='aws_robomaker_warehouse_ShelfD_01_3'>
        <pose>8.09672 2.4872 0 0 -0 0</pose>
        <scale>1 1 1</scale>
        <link name='link'>
          <pose>8.09672 2.4872 0 0 -0 0</pose>
          <velocity>0 0 0 0 -0 0</velocity>
          <acceleration>0 0 0 0 -0 0</acceleration>
          <wrench>0 0 0 0 -0 0</wrench>
        </link>
      </model>
      <model name='aws_robomaker_warehouse_ShelfD_01_4'>
        <pose>4.12179 2.48892 0 0 -0 0</pose>
        <scale>1 1 1</scale>
        <link name='link'>
          <pose>4.12179 2.48892 0 0 -0 0</pose>
          <velocity>0 0 0 0 -0 0</velocity>
          <acceleration>0 0 0 0 -0 0</acceleration>
          <wrench>0 0 0 0 -0 0</wrench>
        </link>
      </model>
      <model name='aws_robomaker_warehouse_ShelfD_01_5'>
        <pose>8.05353 -0.28805 0 0 -0 0</pose>
        <scale>1 1 1</scale>
        <link name='link'>
          <pose>8.05353 -0.28805 0 0 -0 0</pose>
          <velocity>0 0 0 0 -0 0</velocity>
          <acceleration>0 0 0 0 -0 0</acceleration>
          <wrench>0 0 0 0 -0 0</wrench>
        </link>
      </model>
      <model name='aws_robomaker_warehouse_ShelfD_01_6'>
        <pose>4.01037 -0.234414 0 0 -0 0</pose>
        <scale>1 1 1</scale>
        <link name='link'>
          <pose>4.01037 -0.234414 0 0 -0 0</pose>
          <velocity>0 0 0 0 -0 0</velocity>
          <acceleration>0 0 0 0 -0 0</acceleration>
          <wrench>0 0 0 0 -0 0</wrench>
        </link>
      </model>
      <model name='aws_robomaker_warehouse_ShelfD_01_7'>
        <pose>8.01322 -3.11334 0 0 -0 0</pose>
        <scale>1 1 1</scale>
        <link name='link'>
          <pose>8.01322 -3.11334 0 0 -0 0</pose>
          <velocity>0 0 0 0 -0 0</velocity>
          <acceleration>0 0 0 0 -0 0</acceleration>
          <wrench>0 0 0 0 -0 0</wrench>
        </link>
      </model>
      <model name='aws_robomaker_warehouse_ShelfD_01_8'>
        <pose>4.06897 -3.10308 0 0 -0 0</pose>
        <scale>1 1 1</scale>
        <link name='link'>
          <pose>4.06897 -3.10308 0 0 -0 0</pose>
          <velocity>0 0 0 0 -0 0</velocity>
          <acceleration>0 0 0 0 -0 0</acceleration>
          <wrench>0 0 0 0 -0 0</wrench>
        </link>
      </model>
      <model name='aws_robomaker_warehouse_TrashCanC_01'>
        <pose>-3.947395 -3.409701 0 0 -0 1.57</pose>
        <scale>1 1 1</scale>
        <link name='link'>
          <pose>-3.947395 -3.409701 0 0 -0 1.57</pose>
          <velocity>0 0 0 0 -0 0</velocity>
          <acceleration>0 0 0 0 -0 0</acceleration>
          <wrench>0 0 0 0 -0 0</wrench>
        </link>
      </model>
      <model name='desk_chair'>
        <pose>-3.50506 5.97271 0 0 -0 0</pose>
        <scale>1 1 1</scale>
        <link name='link'>
          <pose>-3.50506 5.97271 0 0 -0 0</pose>
          <velocity>0 0 0 0 -0 0</velocity>
          <acceleration>0 0 0 0 -0 0</acceleration>
          <wrench>0 0 0 0 -0 0</wrench>
        </link>
      </model>
      <model name='fire_hose_long_curled'>
        <pose>-4.23806 7.80597 0.043395 -2.2e-05 0.103032 0.001179</pose>
        <scale>1 1 1</scale>
        <link name='coupling'>
          <pose>-4.23806 7.80597 0.043395 -2.2e-05 0.103032 0.001179</pose>
          <velocity>1.3e-05 -0.000112 -3.3e-05 0.002575 0.000296 3.8e-05</velocity>
          <acceleration>0.029122 -0.216932 -0.025888 -2.07191 0.566554 0.049415</acceleration>
          <wrench>0.002912 -0.021693 -0.002589 0 -0 0</wrench>
        </link>
        <link name='link_00'>
          <pose>-4.13859 7.80609 0.03311 0.037584 0.103032 0.001179</pose>
          <velocity>2.3e-05 -8e-05 -6.7e-05 9.2e-05 0.000299 0.000331</velocity>
          <acceleration>0.026208 -0.07867 -0.17571 -0.024144 0.557674 0.54575</acceleration>
          <wrench>0.002621 -0.007867 -0.017571 0 -0 0</wrench>
        </link>
        <link name='link_01'>
          <pose>-4.13859 7.80609 0.03311 0.037144 0.040669 -0.00788</pose>
          <velocity>-1.2e-05 -8.2e-05 -3.2e-05 9.3e-05 -0.000338 0.000397</velocity>
          <acceleration>-0.016304 -0.067628 -0.053012 -0.019999 -0.564475 0.689964</acceleration>
          <wrench>-0.00163 -0.006763 -0.005301 0 -0 0</wrench>
        </link>
        <link name='link_02'>
          <pose>-3.93876 7.80451 0.024978 0.037114 -0.000106 0.00097</pose>
          <velocity>0.000206 -2e-06 -3.8e-05 8.9e-05 -0.00099 -1e-06</velocity>
          <acceleration>0.226408 -0.002341 0.006213 -0.015359 -0.132013 -0.027487</acceleration>
          <wrench>0.022641 -0.000234 0.000621 0 -0 0</wrench>
        </link>
        <link name='link_03'>
          <pose>-3.73876 7.80471 0.025 0.037114 2e-06 0.000148</pose>
          <velocity>2.8e-05 -2e-06 -1e-06 8.8e-05 0.001109 -3e-06</velocity>
          <acceleration>0.01439 0.000226 -0.209734 -0.014387 0.581848 0.00594</acceleration>
          <wrench>0.001439 2.3e-05 -0.020973 0 -0 0</wrench>
        </link>
        <link name='link_04'>
          <pose>-3.53876 7.80473 0.024998 0.037115 -7e-06 -0.005044</pose>
          <velocity>-1.2e-05 -2e-06 0 8.9e-05 -0.0005 -5e-06</velocity>
          <acceleration>0.004145 0.000976 0.029079 -0.013375 0.151076 0.006418</acceleration>
          <wrench>0.000415 9.8e-05 0.002908 0 -0 0</wrench>
        </link>
        <link name='link_05'>
          <pose>-3.33876 7.80373 0.025 0.037118 5e-06 0.007718</pose>
          <velocity>1.5e-05 -6e-06 0.000169 9.5e-05 0.000607 4.3e-05</velocity>
          <acceleration>0.000778 0.000432 0.006028 -0.0144 0.031227 0.003995</acceleration>
          <wrench>7.8e-05 4.3e-05 0.000603 0 -0 0</wrench>
        </link>
        <link name='link_06'>
          <pose>-3.13877 7.80527 0.024998 0.025782 -2e-05 -0.794884</pose>
          <velocity>-9e-06 2.3e-05 -5.2e-05 -0.000941 -0.000366 -5e-05</velocity>
          <acceleration>0.000209 0.002576 0.001678 -0.075173 -0.023052 0.012071</acceleration>
          <wrench>2.1e-05 0.000258 0.000168 0 -0 0</wrench>
        </link>
        <link name='link_07'>
          <pose>-3.01303 7.67702 0.025001 9.3e-05 6e-06 -2.34818</pose>
          <velocity>-3.1e-05 3e-06 0.000191 -9.1e-05 -0.001225 1.7e-05</velocity>
          <acceleration>-0.002715 -0.000786 0.015353 0.020773 -0.119388 0.023027</acceleration>
          <wrench>-0.000271 -7.9e-05 0.001535 0 -0 0</wrench>
        </link>
        <link name='link_08'>
          <pose>-3.14088 7.55087 0.024998 6e-05 -2e-06 3.14036</pose>
          <velocity>-0.000189 2e-06 -4.9e-05 -8.9e-05 -0.007637 -1.2e-05</velocity>
          <acceleration>-0.209289 0.000204 -0.857 3.12306 -0.940748 -3.13938</acceleration>
          <wrench>-0.020929 2e-05 -0.0857 0 -0 0</wrench>
        </link>
        <link name='link_09'>
          <pose>-3.34088 7.55114 0.024999 6e-05 -1e-06 3.1411</pose>
          <velocity>0.000194 1e-06 -0.001535 -7.1e-05 0.007893 -3e-06</velocity>
          <acceleration>0.207703 -0.00067 -0.841585 -3.12824 0.995098 -3.14104</acceleration>
          <wrench>0.02077 -6.7e-05 -0.084158 0 -0 0</wrench>
        </link>
        <link name='link_10'>
          <pose>-3.54088 7.55125 0.024998 5.9e-05 -5e-06 3.14029</pose>
          <velocity>2.2e-05 2e-06 -4.9e-05 -7.5e-05 0.000887 4e-06</velocity>
          <acceleration>0.003303 -0.004467 0.00864 0.020176 0.108125 0.039461</acceleration>
          <wrench>0.00033 -0.000447 0.000864 0 -0 0</wrench>
        </link>
        <link name='link_11'>
          <pose>-3.74088 7.55153 0.025 5.9e-05 2e-06 -3.13817</pose>
          <velocity>-1.7e-05 2e-06 0.000189 -7.6e-05 -0.000671 6e-06</velocity>
          <acceleration>-0.001908 -0.000688 0.01591 0.034925 -0.076641 -0.010585</acceleration>
          <wrench>-0.000191 -6.9e-05 0.001591 0 -0 0</wrench>
        </link>
        <link name='link_12'>
          <pose>-3.94088 7.55087 0.024998 5.9e-05 -1e-05 3.12774</pose>
          <velocity>0.000117 -6.2e-05 -4.3e-05 -9.3e-05 0.000899 5.2e-05</velocity>
          <acceleration>0.133459 -0.121067 0.172437 -3.11379 1.54376 -2.58149</acceleration>
          <wrench>0.013346 -0.012107 0.017244 0 -0 0</wrench>
        </link>
        <link name='link_13'>
          <pose>-4.14086 7.55366 0.025001 3.3e-05 6e-06 -2.33525</pose>
          <velocity>4e-06 -2e-05 0.000118 0.000779 0.000114 -1.8e-05</velocity>
          <acceleration>0.017721 -0.078935 0.169571 2.16533 -0.327991 -0.425643</acceleration>
          <wrench>0.001772 -0.007894 0.016957 0 -0 0</wrench>
        </link>
        <link name='link_14'>
          <pose>-4.26519 7.42405 0.024999 8e-06 -9e-06 -0.783928</pose>
          <velocity>-1.8e-05 1e-06 -3.2e-05 -5.5e-05 -0.000757 9.8e-05</velocity>
          <acceleration>-0.018868 -0.048411 -0.173673 -2.3117 -1.43328 -3.09348</acceleration>
          <wrench>-0.001887 -0.004841 -0.017367 0 -0 0</wrench>
        </link>
        <link name='link_15'>
          <pose>-4.13806 7.29718 0.025001 -1e-06 7e-06 -0.004169</pose>
          <velocity>1.6e-05 2e-06 0.000178 -3.4e-05 0.000641 -1e-05</velocity>
          <acceleration>0.015482 -0.020368 0.104418 0.856649 0.618935 0.059891</acceleration>
          <wrench>0.001548 -0.002037 0.010442 0 -0 0</wrench>
        </link>
        <link name='link_16'>
          <pose>-3.93806 7.29635 0.024998 -1e-06 -3e-06 0.003511</pose>
          <velocity>0.000208 -1e-06 -0.000193 -2e-06 -0.000789 1e-05</velocity>
          <acceleration>0.185433 -0.048353 -0.336393 -2.25605 -1.539 -3.10638</acceleration>
          <wrench>0.018543 -0.004835 -0.033639 0 -0 0</wrench>
        </link>
        <link name='link_17'>
          <pose>-3.73806 7.29705 0.024999 -1e-06 -0 0.004073</pose>
          <velocity>1.6e-05 5e-06 0.000169 9e-06 0.000639 -6.4e-05</velocity>
          <acceleration>0.001444 -0.019311 -0.003856 0.790695 0.057302 0.025793</acceleration>
          <wrench>0.000144 -0.001931 -0.000386 0 -0 0</wrench>
        </link>
        <link name='link_18'>
          <pose>-3.53806 7.29787 0.024998 -8e-06 0.001433 -0.000777</pose>
          <velocity>2.3e-05 -2.8e-05 0.000157 1e-05 0.000909 0.00014</velocity>
          <acceleration>0.036955 -0.033949 0.148016 0.655503 1.46974 -0.07924</acceleration>
          <wrench>0.003696 -0.003395 0.014802 0 -0 0</wrench>
        </link>
        <link name='link_19'>
          <pose>-3.33806 7.29771 0.024712 0.000136 -0.152025 -0.001724</pose>
          <velocity>7e-06 1.3e-05 -0.00017 2.1e-05 -0.000746 4.3e-05</velocity>
          <acceleration>-0.009283 0.037654 -0.111239 0.399924 -0.874395 0.428994</acceleration>
          <wrench>-0.000928 0.003765 -0.011124 0 -0 0</wrench>
        </link>
        <link name='nozzle'>
          <pose>-3.14037 7.29737 0.055 -7.4e-05 0.079096 3.14065</pose>
          <velocity>-1.2e-05 1.3e-05 -1.9e-05 2.1e-05 5.3e-05 -2.5e-05</velocity>
          <acceleration>-0.015464 0.016773 -0.020799 0.255008 0.016861 -0.017641</acceleration>
          <wrench>-0.001546 0.001677 -0.00208 0 -0 0</wrench>
        </link>
      </model>
      <model name='fire_hydrant'>
        <pose>-4.35255 8.86049 0 0 -0 0</pose>
        <scale>1 1 1</scale>
        <link name='link'>
          <pose>-4.35255 8.86049 0 0 -0 0</pose>
          <velocity>0 0 0 0 -0 0</velocity>
          <acceleration>0 0 0 0 -0 0</acceleration>
          <wrench>0 0 0 0 -0 0</wrench>
        </link>
      </model>
      <model name='ground_plane'>
        <pose>0 0 0 0 -0 0</pose>
        <scale>1 1 1</scale>
        <link name='link'>
          <pose>0 0 0 0 -0 0</pose>
          <velocity>0 0 0 0 -0 0</velocity>
          <acceleration>0 0 0 0 -0 0</acceleration>
          <wrench>0 0 0 0 -0 0</wrench>
        </link>
      </model>
      <model name='servicebot'>
        <pose>9.93686 6.82726 0.002543 0.004868 -0 1.62041</pose>
        <scale>1 1 1</scale>
        <link name='link'>
          <pose>9.93686 6.82726 0.002543 0.004868 -0 1.62041</pose>
          <velocity>0 0 0 0 -0 0</velocity>
          <acceleration>-0.00016 0.003244 0.005951 -1.2772 -0.063072 -0.000128</acceleration>
          <wrench>-0.00016 0.003244 0.005951 0 -0 0</wrench>
        </link>
      </model>
      <model name='walls'>
        <pose>2.77787 1.7398 0 0 -0 0</pose>
        <scale>1 1 1</scale>
        <link name='Wall_13'>
          <pose>2.77787 -5.6852 0 0 -0 0</pose>
          <velocity>0 0 0 0 -0 0</velocity>
          <acceleration>0 0 0 0 -0 0</acceleration>
          <wrench>0 0 0 0 -0 0</wrench>
        </link>
        <link name='Wall_14'>
          <pose>10.2029 -5.6852 0 0 -0 0</pose>
          <velocity>0 0 0 0 -0 0</velocity>
          <acceleration>0 0 0 0 -0 0</acceleration>
          <wrench>0 0 0 0 -0 0</wrench>
        </link>
        <link name='Wall_17'>
          <pose>10.2029 1.7398 0 0 -0 1.5708</pose>
          <velocity>0 0 0 0 -0 0</velocity>
          <acceleration>0 0 0 0 -0 0</acceleration>
          <wrench>0 0 0 0 -0 0</wrench>
        </link>
        <link name='Wall_19'>
          <pose>2.77787 9.1648 0 0 -0 3.14159</pose>
          <velocity>0 0 0 0 -0 0</velocity>
          <acceleration>0 0 0 0 -0 0</acceleration>
          <wrench>0 0 0 0 -0 0</wrench>
        </link>
        <link name='Wall_20'>
          <pose>-4.64713 9.1648 0 0 -0 0</pose>
          <velocity>0 0 0 0 -0 0</velocity>
          <acceleration>0 0 0 0 -0 0</acceleration>
          <wrench>0 0 0 0 -0 0</wrench>
        </link>
        <link name='Wall_21'>
          <pose>-4.64713 1.7398 0 0 0 -1.5708</pose>
          <velocity>0 0 0 0 -0 0</velocity>
          <acceleration>0 0 0 0 -0 0</acceleration>
          <wrench>0 0 0 0 -0 0</wrench>
        </link>
      </model>
      <light name='sun'>
        <pose>0 0 10 0 -0 0</pose>
      </light>
    </state>
    <gui fullscreen='0'>
      <camera name='user_camera'>
        <pose>7.05842 1.19117 26.6219 3e-06 1.5578 1.5682</pose>
        <view_controller>orbit</view_controller>
        <projection_type>perspective</projection_type>
      </camera>
    </gui>
    <model name="turtlebot3_dqn_obstacle1">
      <plugin name="obstacle1" filename="libobstacle5.so"/>
      <include>
        <pose>0.5 1.5 0 0 0 0</pose>
        <uri>model://turtlebot3_dqn_world/obstacle4</uri>
      </include>
    </model>
    
    <model name="turtlebot3_dqn_obstacle2">
      <plugin name="obstacle2" filename="libobstacle6.so"/>
      <include>
        <pose>0 0 0 0 0 0</pose>
        <uri>model://turtlebot3_dqn_world/obstacle5</uri>
      </include>
    </model>
    
    <model name="turtlebot3_dqn_obstacle3">
      <plugin name="obstacle3" filename="libobstacle7.so"/>
      <include>
        <pose>0 0 0 0 0 0</pose>
        <uri>model://turtlebot3_dqn_world/obstacle6</uri>
      </include>
    </model>
    
  </world>
</sdf>
