<?xml version="1.0" ?>
<!-- =================================================================================== -->
<!-- |    This document was autogenerated by xacro from robot_model_1.urdf.xacro       | -->
<!-- |    EDITING THIS FILE BY HAND IS NOT RECOMMENDED                                 | -->
<!-- =================================================================================== -->
<robot name="turtlebot3_waffle_4">
  <!-- Materials -->
  <material name="black">
    <color rgba="0.0 0.0 0.0 1.0"/>
  </material>
  <material name="dark">
    <color rgba="0.3 0.3 0.3 1.0"/>
  </material>
  <material name="light_black">
    <color rgba="0.4 0.4 0.4 1.0"/>
  </material>
  <material name="blue">
    <color rgba="0.0 0.0 0.8 1.0"/>
  </material>
  <material name="green">
    <color rgba="0.0 0.8 0.0 1.0"/>
  </material>
  <material name="grey">
    <color rgba="0.5 0.5 0.5 1.0"/>
  </material>
  <material name="orange">
    <color rgba="1.0 0.4235 0.0392 1.0"/>
  </material>
  <material name="brown">
    <color rgba="0.8706 0.8118 0.7647 1.0"/>
  </material>
  <material name="red">
    <color rgba="0.8 0.0 0.0 1.0"/>
  </material>
  <material name="white">
    <color rgba="1.0 1.0 1.0 1.0"/>
  </material>
  <!-- Links and joints with namespace -->
  <link name="robot4/base_footprint"/>
  <joint name="robot4/base_joint" type="fixed">
    <parent link="robot4/base_footprint"/>
    <child link="robot4/base_link"/>
    <origin rpy="0 0 0" xyz="0 0 0.010"/>
  </joint>
  <link name="robot4/base_link">
    <visual>
      <origin rpy="0 0 0" xyz="-0.064 0 0.0"/>
      <geometry>
        <mesh filename="package://sim_gazebo/models/turtlebot3_common/meshes/waffle_base.dae" scale="0.001 0.001 0.001"/>
      </geometry>
      <material name="light_black"/>
    </visual>
    <collision>
      <origin rpy="0 0 0" xyz="-0.064 0 0.047"/>
      <geometry>
        <box size="0.266 0.266 0.094"/>
      </geometry>
    </collision>
    <inertial>
      <origin rpy="0 0 0" xyz="0 0 0"/>
      <mass value="1.3729096e+00"/>
      <inertia ixx="8.7002718e-03" ixy="-4.7576583e-05" ixz="1.1160499e-04" iyy="8.6195418e-03" iyz="-3.5422299e-06" izz="1.4612727e-02"/>
    </inertial>
  </link>
  <joint name="robot4/wheel_left_joint" type="continuous">
    <parent link="robot4/base_link"/>
    <child link="robot4/wheel_left_link"/>
    <origin rpy="-1.57 0 0" xyz="0.0 0.144 0.023"/>
    <axis xyz="0 0 1"/>
  </joint>
  <link name="robot4/wheel_left_link">
    <visual>
      <origin rpy="1.57 0 0" xyz="0 0 0"/>
      <geometry>
        <mesh filename="package://sim_gazebo/models/turtlebot3_common/meshes/tire.dae" scale="0.001 0.001 0.001"/>
      </geometry>
      <material name="dark"/>
    </visual>
    <collision>
      <origin rpy="0 0 0" xyz="0 0 0"/>
      <geometry>
        <cylinder length="0.018" radius="0.033"/>
      </geometry>
    </collision>
    <inertial>
      <origin xyz="0 0 0"/>
      <mass value="2.8498940e-02"/>
      <inertia ixx="1.1175580e-05" ixy="-4.2369783e-11" ixz="-5.9381719e-09" iyy="1.1192413e-05" iyz="-1.4400107e-11" izz="2.0712558e-05"/>
    </inertial>
  </link>
  <!-- Similar updates for all other joints and links -->
  <joint name="robot4/wheel_right_joint" type="continuous">
    <parent link="robot4/base_link"/>
    <child link="robot4/wheel_right_link"/>
    <origin rpy="-1.57 0 0" xyz="0.0 -0.144 0.023"/>
    <axis xyz="0 0 1"/>
  </joint>
  <link name="robot4/wheel_right_link">
    <visual>
      <origin rpy="1.57 0 0" xyz="0 0 0"/>
      <geometry>
        <mesh filename="package://sim_gazebo/models/turtlebot3_common/meshes/tire.dae" scale="0.001 0.001 0.001"/>
      </geometry>
      <material name="dark"/>
    </visual>
    <collision>
      <origin rpy="0 0 0" xyz="0 0 0"/>
      <geometry>
        <cylinder length="0.018" radius="0.033"/>
      </geometry>
    </collision>
    <inertial>
      <origin xyz="0 0 0"/>
      <mass value="2.8498940e-02"/>
      <inertia ixx="1.1175580e-05" ixy="-4.2369783e-11" ixz="-5.9381719e-09" iyy="1.1192413e-05" iyz="-1.4400107e-11" izz="2.0712558e-05"/>
    </inertial>
  </link>
  <joint name="robot4/caster_back_right_joint" type="fixed">
    <parent link="robot4/base_link"/>
    <child link="robot4/caster_back_right_link"/>
    <origin rpy="-1.57 0 0" xyz="-0.177 -0.064 -0.004"/>
  </joint>
  <link name="robot4/caster_back_right_link">
    <collision>
      <origin rpy="0 0 0" xyz="0 0.001 0"/>
      <geometry>
        <box size="0.030 0.009 0.020"/>
      </geometry>
    </collision>
    <inertial>
      <origin xyz="0 0 0"/>
      <mass value="0.005"/>
      <inertia ixx="0.001" ixy="0.0" ixz="0.0" iyy="0.001" iyz="0.0" izz="0.001"/>
    </inertial>
  </link>
  <joint name="robot4/caster_back_left_joint" type="fixed">
    <parent link="robot4/base_link"/>
    <child link="robot4/caster_back_left_link"/>
    <origin rpy="-1.57 0 0" xyz="-0.177 0.064 -0.004"/>
  </joint>
  <link name="robot4/caster_back_left_link">
    <collision>
      <origin rpy="0 0 0" xyz="0 0.001 0"/>
      <geometry>
        <box size="0.030 0.009 0.020"/>
      </geometry>
    </collision>
    <inertial>
      <origin xyz="0 0 0"/>
      <mass value="0.005"/>
      <inertia ixx="0.001" ixy="0.0" ixz="0.0" iyy="0.001" iyz="0.0" izz="0.001"/>
    </inertial>
  </link>
  <joint name="robot4/imu_joint" type="fixed">
    <parent link="robot4/base_link"/>
    <child link="robot4/imu_link"/>
    <origin rpy="0 0 0" xyz="0.0 0 0.068"/>
  </joint>
  <link name="robot4/imu_link"/>
  <joint name="robot4/scan_joint" type="fixed">
    <parent link="robot4/base_link"/>
    <child link="robot4/base_scan"/>
    <origin rpy="0 0 0" xyz="-0.064 0 0.122"/>
  </joint>
  <link name="robot4/base_scan">
    <visual>
      <origin rpy="0 0 0" xyz="0 0 0"/>
      <geometry>
        <mesh filename="package://sim_gazebo/models/turtlebot3_common/meshes/lds.dae" scale="0.001 0.001 0.001"/>
      </geometry>
      <material name="dark"/>
    </visual>
    <collision>
      <origin rpy="0 0 0" xyz="0.015 0 -0.0065"/>
      <geometry>
        <cylinder length="0.0315" radius="0.055"/>
      </geometry>
    </collision>
    <inertial>
      <mass value="0.114"/>
      <origin xyz="0 0 0"/>
      <inertia ixx="0.001" ixy="0.0" ixz="0.0" iyy="0.001" iyz="0.0" izz="0.001"/>
    </inertial>
  </link>
  <joint name="robot4/camera_joint" type="fixed">
    <origin rpy="0 0 0" xyz="0.064 -0.065 0.094"/>
    <parent link="robot4/base_link"/>
    <child link="robot4/camera_link"/>
  </joint>
  <link name="robot4/camera_link">
    <visual>
      <origin rpy="1.57 0 1.57" xyz="0 0 0"/>
      <geometry>
        <mesh filename="package://sim_gazebo/models/turtlebot3_common/meshes/r200.dae"/>
      </geometry>
    </visual>
    <collision>
      <origin rpy="0 0 0" xyz="0.003 0.065 0.007"/>
      <geometry>
        <box size="0.012 0.132 0.020"/>
      </geometry>
    </collision>
    <!-- This inertial field needs doesn't contain reliable data!! -->
    <!--   <inertial>
      <mass value="0.564" />
      <origin xyz="0 0 0" />
      <inertia ixx="0.003881243" ixy="0.0" ixz="0.0"
               iyy="0.000498940" iyz="0.0"
               izz="0.003879257" />
    </inertial>-->
  </link>
  <joint name="robot4/camera_rgb_joint" type="fixed">
    <origin rpy="0 0 0" xyz="0.005 0.018 0.013"/>
    <!-- <origin xyz="${r200_cam_rgb_px} ${r200_cam_rgb_py} ${r200_cam_rgb_pz}" rpy="0 0 0"/> -->
    <parent link="robot4/camera_link"/>
    <child link="robot4/camera_rgb_frame"/>
  </joint>
  <link name="robot4/camera_rgb_frame"/>
  <joint name="robot4/camera_rgb_optical_joint" type="fixed">
    <origin rpy="-1.57 0 -1.57" xyz="0 0 0"/>
    <parent link="robot4/camera_rgb_frame"/>
    <child link="robot4/camera_rgb_optical_frame"/>
  </joint>
  <link name="robot4/camera_rgb_optical_frame"/>
  <joint name="robot4/camera_depth_joint" type="fixed">
    <origin rpy="0 0 0" xyz="0.005 0.028 0.013"/>
    <!-- <origin xyz="${r200_cam_rgb_px} ${r200_cam_rgb_py + r200_cam_depth_offset} ${r200_cam_rgb_pz}" rpy="0 0 0"/> -->
    <parent link="robot4/camera_link"/>
    <child link="robot4/camera_depth_frame"/>
  </joint>
  <link name="robot4/camera_depth_frame"/>
  <joint name="robot4/camera_depth_optical_joint" type="fixed">
    <origin rpy="-1.57 0 -1.57" xyz="0 0 0"/>
    <parent link="robot4/camera_depth_frame"/>
    <child link="robot4/camera_depth_optical_frame"/>
  </joint>
  <link name="robot4/camera_depth_optical_frame"/>
</robot>
